Workbook

Sheet Premissas
B2: MODELO INCENTIVO PRODUTIVIDADE — JULHO E AGOSTO | GPA | MENSAL + DIÁRIO
B4: PARÂMETROS EDITÁVEIS
B6: Faixa | C6: Fator mín | D6: Fator máx | E6: Valor MENSAL | F6: Valor DIÁRIO
B7: Não atingiu | C7: 0 | D7: 0.9999 | E7: 0 | F7: =IF(E7=0,0,E7/$C$16) -> 0
B8: 1,00 – 1,19 | C8: 1 | D8: 1.1999 | E8: 100 | F8: =IF(E8=0,0,E8/$C$16) -> 3.8461538
B9: 1,20 – 1,39 | C9: 1.2 | D9: 1.3999 | E9: 200 | F9: =IF(E9=0,0,E9/$C$16) -> 7.6923077
B10: 1,40 – 1,59 | C10: 1.4 | D10: 1.5999 | E10: 350 | F10: =IF(E10=0,0,E10/$C$16) -> 13.461538
B11: 1,60 – 1,99 | C11: 1.6 | D11: 1.8 | E11: 500 | F11: =IF(E11=0,0,E11/$C$16) -> 19.230769
B12: ≥ 2,00 (teto) | C12: 1.9 | D12: 2 | E12: 750 | F12: =IF(E12=0,0,E12/$C$16) -> 28.846154
B15: Horas Efetivas | C15: 5.5
B16: Dias úteis | C16: 26
B17: Teto mensal HC | C17: 750
B19: METAS CD1942
B20: Atividade | C20: Meta
B21: CARREGAMENTO | C21: 22
B22: RECEBIMENTO | C22: 17
B23: PUXADA RECEB | C23: 16
B24: ATIVIDADE OP. EMP. | C24: 20
B27: REGRAS
B28: 1. Empresa: se EMPRESA preenchida usa o valor; se em branco: =SE(ESQUERDA(USUÁRIO;1)="T";"TERCEIRA";"GPA").
B29: 2. Elegível: EMPRESA_AJUSTADA = GPA. Exclui TERCEIRA/TERCEIRO e SEPARAÇÃO.
B30: 3. Fator = PRODUTIVIDADE/META. Consolidação = melhor fator do HC no MÊS.
B31: 4. Pagamento MENSAL pela faixa. Valor DIÁRIO = mensal ÷ dias úteis (B13).
B32: 5. Meta em branco/zero → meta padrão CD1942. Teto = B14.
B33: 6. Simulação JULHO e AGOSTO. Base original completa na aba Base.
B34: 7. Amarelo + azul = editável. Demais células = fórmulas.
B37: CONTROLE
B38: HCs Jul | C38: =COUNTIFS(Consolidado_HC!A:A,7) -> 788
B39: Custo Jul | C39: =SUMIF(Consolidado_HC!A:A,7,Consolidado_HC!L:L) -> 214000
B40: HCs Ago | C40: =COUNTIFS(Consolidado_HC!A:A,8) -> 805
B41: Custo Ago | C41: =SUMIF(Consolidado_HC!A:A,8,Consolidado_HC!L:L) -> 204500

Sheet Simulação
A1: Faixa (Carregamento 409 FLV = 24 ) | B1: Fator mín | C1: Fator máx | D1: Alcance Qtd | E1: Qtd TT Acu. | F1: Aumento Faixa | H1: CD | I1: Indicador | J1: Categoria | K1: Meta | L1: Média Geral | M1: Cód. Unidade de Medida
A2: Alcance dia | B2: 0 | C2: 0.9999 | D2: =24*B9 -> 132 | E2: 0 | F2: 0 | H2: 409 | I2: ATIVIDADE OP. EMP. | J2: CARNES | K2: 26.991741 | L2: =AVERAGE(K2:K4) -> 25.96294 | M2: 2
A3: 1.19 | B3: 1 | C3: 1.1999 | D3: =D2+E3 -> 157.08 | E3: =D2*19% -> 25.08 | F3: =ABS(D2-D3) -> 25.08 | H3: 409 | I3: ATIVIDADE OP. EMP. | J3: F.L.V | K3: 26.171763 | M3: 2
A4: 1.39 | B4: 1.2 | C4: 1.3999 | D4: =D2+E4 -> 183.48 | E4: =D2*39% -> 51.48 | F4: =ABS(D3-D4) -> 26.4 | H4: 409 | I4: ATIVIDADE OP. EMP. | J4: MERCEARIA | K4: 24.725317 | M4: 2
A5: 1.59 | B5: 1.4 | C5: 1.5999 | D5: =D2+E5 -> 209.88 | E5: =D2*59% -> 77.88 | F5: =ABS(D4-D5) -> 26.4 | H5: 409 | I5: CARREGAMENTO | J5: CARNES | K5: 15.819599 | L5: =AVERAGE(K5:K7) -> 21.764179 | M5: 1
A6: 1.79 | B6: 1.6 | C6: 1.8 | D6: =D2+E6 -> 236.28 | E6: =D2*79% -> 104.28 | F6: =ABS(D5-D6) -> 26.4 | H6: 409 | I6: CARREGAMENTO | J6: F.L.V | K6: 24.390974 | M6: 1
A7: ≥ 2,00 (teto) | B7: 1.9 | C7: 2 | D7: =D2+E7 -> 264 | E7: =D2*100% -> 132 | F7: =ABS(D6-D7) -> 27.72 | H7: 409 | I7: CARREGAMENTO | J7: MERCEARIA | K7: 25.081963 | M7: 1
H8: 409 | I8: PUXADA RECEB | J8: CARNES | K8: 20.014969 | L8: =AVERAGE(K8:K10) -> 21.914432 | M8: 34
A9: Média Hora | B9: 5.5 | H9: 409 | I9: PUXADA RECEB | J9: F.L.V | K9: 23.865604 | M9: 34
A10: Faixa (Carregamento 409 FLV = 24 ) | B10: Fator máx | C10: Valor (Olpn/ PLT ID) | D10: Valor DIÁRIO | E10: Valor Mensal | H10: 409 | I10: PUXADA RECEB | J10: MERCEARIA | K10: 21.862723 | M10: 34
A11: Alcance dia | B11: 0.9999 | C11: 0 | D11: =IF(C11=0,0,C11/$B$16) -> 0 | E11: =D11*26 -> 0 | H11: 409 | I11: RECEBIMENTO | J11: CARNES | K11: 16.771957 | L11: =AVERAGE(K11:K13) -> 23.031803 | M11: 4
A12: 1.19 | B12: 1.1999 | C12: 0.22 | D12: =C12*F3 -> 5.5176 | E12: =D12*26 -> 143.4576 | G12: =E12/25 -> 5.738304 | H12: 409 | I12: RECEBIMENTO | J12: F.L.V | K12: 20.718359 | M12: 4
A13: 1.39 | B13: 1.3999 | C13: 0.22 | D13: =C13*F4 -> 5.808 | E13: =D13*26 -> 151.008 | H13: 409 | I13: RECEBIMENTO | J13: MERCEARIA | K13: 31.605093 | M13: 4
A14: 1.59 | B14: 1.5999 | C14: 0.22 | D14: =C14*F5 -> 5.808 | E14: =D14*26 -> 151.008
A15: 1.79 | B15: 1.8 | C15: 0.22 | D15: =C15*F6 -> 5.808 | E15: =D15*26 -> 151.008 | H15: CD | I15: Função | J15: Cód. Unidade de Medida
A16: ≥ 2,00 (teto) | B16: 2 | C16: 0.22 | D16: =C16*F7 -> 6.0984 | E16: =D16*26 -> 158.5584 | H16: 409 | I16: Carregamento | J16: 1
A17: TT | D17: =SUM(D11:D16) -> 29.04 | E17: =SUM(E11:E16) -> 755.04 | H17: 409 | I17: Carregamento+Empilhadeira | J17: 12
H18: 409 | I18: Carregamento+Empilhadeira+Puxada | J18: 123
A19: REGRAS | H19: 409 | I19: Carregamento+Empilhadeira+Puxada+Recebimento | J19: 1234
A20: 1. Utilizar metricas de valores por superação de meta | H20: 409 | I20: Carregamento+Puxada | J20: 13
A21: 2. Para atividades com sinergia trazer média | H21: 409 | I21: Carregamento+Recebimento | J21: 14
H22: 409 | I22: Empilhadeira | J22: 2
H23: 409 | I23: Empilhadeira+Puxada | J23: 23
H24: 409 | I24: Empilhadeira+Puxada+Recebimento | J24: 234
H25: 409 | I25: Empilhadeira+Recebimento | J25: 24
H26: 409 | I26: Puxada | J26: 3
H27: 409 | I27: Puxada+Recebimento | J27: 34
H28: 409 | I28: Recebimento | J28: 4

Sheet AllIn_Apoio
B1: SIMULAÇÃO ALL-IN — CAMISA 10 / APOIO / INVENTÁRIO / ROUPARIA
B3: PREMISSAS (editáveis — amarelo)
B5: Mês referência | C5: 8
B6: Dias úteis (ganho diário) | C6: =Premissas!C16 -> 26
B7: Teto mensal por HC (R$) | C7: =Premissas!C17 -> 750
B9: FAIXAS (mesmas do operacional — referenciam Premissas)
B10: Faixa | C10: Fator mín | D10: Fator máx | E10: Valor MENSAL | F10: Valor DIÁRIO
B11: =Premissas!B7 -> Não atingiu | C11: =Premissas!C7 -> 0 | D11: =Premissas!D7 -> 0.9999 | E11: =Premissas!E7 -> 0 | F11: =Premissas!F7 -> 0
B12: =Premissas!B8 -> 1,00 – 1,19 | C12: =Premissas!C8 -> 1 | D12: =Premissas!D8 -> 1.1999 | E12: =Premissas!E8 -> 100 | F12: =Premissas!F8 -> 3.8461538
B13: =Premissas!B9 -> 1,20 – 1,39 | C13: =Premissas!C9 -> 1.2 | D13: =Premissas!D9 -> 1.3999 | E13: =Premissas!E9 -> 200 | F13: =Premissas!F9 -> 7.6923077
B14: =Premissas!B10 -> 1,40 – 1,59 | C14: =Premissas!C10 -> 1.4 | D14: =Premissas!D10 -> 1.5999 | E14: =Premissas!E10 -> 350 | F14: =Premissas!F10 -> 13.461538
B15: =Premissas!B11 -> 1,60 – 1,99 | C15: =Premissas!C11 -> 1.6 | D15: =Premissas!D11 -> 1.8 | E15: =Premissas!E11 -> 500 | F15: =Premissas!F11 -> 19.230769
B16: =Premissas!B12 -> ≥ 2,00 (teto) | C16: =Premissas!C12 -> 1.9 | D16: =Premissas!D12 -> 2 | E16: =Premissas!E12 -> 750 | F16: =Premissas!F12 -> 28.846154
B18: INPUT POR CD — ALL-IN (editável)
B19: Preencha Meta, Realizado e Qtd de HCs Camisa 10/Apoio. Fator, faixa e valores calculam sozinhos.
B20: CD | C20: META_ALLIN | D20: REALIZADO_ALLIN | E20: FATOR | F20: FAIXA | G20: VALOR_MENSAL_HC | H20: VALOR_DIARIO_HC | I20: QTD_HCs_APOIO | J20: CUSTO_MENSAL_CD | K20: CUSTO_DIARIO_CD
B21: 1942 | C21: 470 | D21: 500 | E21: =IF(OR(C21="",C21=0,D21=""),"",D21/C21) -> 1.0638298 | F21: =IF(E21="","",IF(E21<Premissas!$C$8,"< 1,00",IF(E21<Premissas!$C$9,"1,00 – 1,19",IF(E21<Premissas!$C$10,"1,20 – 1,39",IF(E21<Premissas!$C$11,"1,40 – 1,59",IF(E21<Premissas!$C$12,"1,60 – 1,99","≥ 2,00")))))) -> 1,00 – 1,19 | G21: =IF(E21="","",MIN(Premissas!$C$17,IF(E21<Premissas!$C$8,Premissas!$E$7,IF(E21<Premissas!$C$9,Premissas!$E$8,IF(E21<Premissas!$C$10,Premissas!$E$9,IF(E21<Premissas!$C$11,Premissas!$E$10,IF(E21<Premissas!$C$12,Premissas!$E$11,Premissas!$E$12))))))) -> 100 | H21: =IF(OR(G21="",G21=0),0,G21/$C$6) -> 3.8461538 | I21: 5 | J21: =IF(OR(G21="",I21=""),0,G21*I21) -> 500 | K21: =IF(OR(J21="",J21=0),0,J21/$C$6) -> 19.230769
B22: 409 | E22: =IF(OR(C22="",C22=0,D22=""),"",D22/C22) | F22: =IF(E22="","",IF(E22<Premissas!$C$8,"< 1,00",IF(E22<Premissas!$C$9,"1,00 – 1,19",IF(E22<Premissas!$C$10,"1,20 – 1,39",IF(E22<Premissas!$C$11,"1,40 – 1,59",IF(E22<Premissas!$C$12,"1,60 – 1,99","≥ 2,00")))))) | G22: =IF(E22="","",MIN(Premissas!$C$17,IF(E22<Premissas!$C$8,Premissas!$E$7,IF(E22<Premissas!$C$9,Premissas!$E$8,IF(E22<Premissas!$C$10,Premissas!$E$9,IF(E22<Premissas!$C$11,Premissas!$E$10,IF(E22<Premissas!$C$12,Premissas!$E$11,Premissas!$E$12))))))) | H22: =IF(OR(G22="",G22=0),0,G22/$C$6) -> 0 | J22: =IF(OR(G22="",I22=""),0,G22*I22) -> 0 | K22: =IF(OR(J22="",J22=0),0,J22/$C$6) -> 0
B23: 930 | E23: =IF(OR(C23="",C23=0,D23=""),"",D23/C23) | F23: =IF(E23="","",IF(E23<Premissas!$C$8,"< 1,00",IF(E23<Premissas!$C$9,"1,00 – 1,19",IF(E23<Premissas!$C$10,"1,20 – 1,39",IF(E23<Premissas!$C$11,"1,40 – 1,59",IF(E23<Premissas!$C$12,"1,60 – 1,99","≥ 2,00")))))) | G23: =IF(E23="","",MIN(Premissas!$C$17,IF(E23<Premissas!$C$8,Premissas!$E$7,IF(E23<Premissas!$C$9,Premissas!$E$8,IF(E23<Premissas!$C$10,Premissas!$E$9,IF(E23<Premissas!$C$11,Premissas!$E$10,IF(E23<Premissas!$C$12,Premissas!$E$11,Premissas!$E$12))))))) | H23: =IF(OR(G23="",G23=0),0,G23/$C$6) -> 0 | J23: =IF(OR(G23="",I23=""),0,G23*I23) -> 0 | K23: =IF(OR(J23="",J23=0),0,J23/$C$6) -> 0
B24: 1953 | E24: =IF(OR(C24="",C24=0,D24=""),"",D24/C24) | F24: =IF(E24="","",IF(E24<Premissas!$C$8,"< 1,00",IF(E24<Premissas!$C$9,"1,00 – 1,19",IF(E24<Premissas!$C$10,"1,20 – 1,39",IF(E24<Premissas!$C$11,"1,40 – 1,59",IF(E24<Premissas!$C$12,"1,60 – 1,99","≥ 2,00")))))) | G24: =IF(E24="","",MIN(Premissas!$C$17,IF(E24<Premissas!$C$8,Premissas!$E$7,IF(E24<Premissas!$C$9,Premissas!$E$8,IF(E24<Premissas!$C$10,Premissas!$E$9,IF(E24<Premissas!$C$11,Premissas!$E$10,IF(E24<Premissas!$C$12,Premissas!$E$11,Premissas!$E$12))))))) | H24: =IF(OR(G24="",G24=0),0,G24/$C$6) -> 0 | J24: =IF(OR(G24="",I24=""),0,G24*I24) -> 0 | K24: =IF(OR(J24="",J24=0),0,J24/$C$6) -> 0
B25: 1965 | E25: =IF(OR(C25="",C25=0,D25=""),"",D25/C25) | F25: =IF(E25="","",IF(E25<Premissas!$C$8,"< 1,00",IF(E25<Premissas!$C$9,"1,00 – 1,19",IF(E25<Premissas!$C$10,"1,20 – 1,39",IF(E25<Premissas!$C$11,"1,40 – 1,59",IF(E25<Premissas!$C$12,"1,60 – 1,99","≥ 2,00")))))) | G25: =IF(E25="","",MIN(Premissas!$C$17,IF(E25<Premissas!$C$8,Premissas!$E$7,IF(E25<Premissas!$C$9,Premissas!$E$8,IF(E25<Premissas!$C$10,Premissas!$E$9,IF(E25<Premissas!$C$11,Premissas!$E$10,IF(E25<Premissas!$C$12,Premissas!$E$11,Premissas!$E$12))))))) | H25: =IF(OR(G25="",G25=0),0,G25/$C$6) -> 0 | J25: =IF(OR(G25="",I25=""),0,G25*I25) -> 0 | K25: =IF(OR(J25="",J25=0),0,J25/$C$6) -> 0
B26: 1974 | E26: =IF(OR(C26="",C26=0,D26=""),"",D26/C26) | F26: =IF(E26="","",IF(E26<Premissas!$C$8,"< 1,00",IF(E26<Premissas!$C$9,"1,00 – 1,19",IF(E26<Premissas!$C$10,"1,20 – 1,39",IF(E26<Premissas!$C$11,"1,40 – 1,59",IF(E26<Premissas!$C$12,"1,60 – 1,99","≥ 2,00")))))) | G26: =IF(E26="","",MIN(Premissas!$C$17,IF(E26<Premissas!$C$8,Premissas!$E$7,IF(E26<Premissas!$C$9,Premissas!$E$8,IF(E26<Premissas!$C$10,Premissas!$E$9,IF(E26<Premissas!$C$11,Premissas!$E$10,IF(E26<Premissas!$C$12,Premissas!$E$11,Premissas!$E$12))))))) | H26: =IF(OR(G26="",G26=0),0,G26/$C$6) -> 0 | J26: =IF(OR(G26="",I26=""),0,G26*I26) -> 0 | K26: =IF(OR(J26="",J26=0),0,J26/$C$6) -> 0
B27: 1979 | E27: =IF(OR(C27="",C27=0,D27=""),"",D27/C27) | F27: =IF(E27="","",IF(E27<Premissas!$C$8,"< 1,00",IF(E27<Premissas!$C$9,"1,00 – 1,19",IF(E27<Premissas!$C$10,"1,20 – 1,39",IF(E27<Premissas!$C$11,"1,40 – 1,59",IF(E27<Premissas!$C$12,"1,60 – 1,99","≥ 2,00")))))) | G27: =IF(E27="","",MIN(Premissas!$C$17,IF(E27<Premissas!$C$8,Premissas!$E$7,IF(E27<Premissas!$C$9,Premissas!$E$8,IF(E27<Premissas!$C$10,Premissas!$E$9,IF(E27<Premissas!$C$11,Premissas!$E$10,IF(E27<Premissas!$C$12,Premissas!$E$11,Premissas!$E$12))))))) | H27: =IF(OR(G27="",G27=0),0,G27/$C$6) -> 0 | J27: =IF(OR(G27="",I27=""),0,G27*I27) -> 0 | K27: =IF(OR(J27="",J27=0),0,J27/$C$6) -> 0
B28: 7801 | E28: =IF(OR(C28="",C28=0,D28=""),"",D28/C28) | F28: =IF(E28="","",IF(E28<Premissas!$C$8,"< 1,00",IF(E28<Premissas!$C$9,"1,00 – 1,19",IF(E28<Premissas!$C$10,"1,20 – 1,39",IF(E28<Premissas!$C$11,"1,40 – 1,59",IF(E28<Premissas!$C$12,"1,60 – 1,99","≥ 2,00")))))) | G28: =IF(E28="","",MIN(Premissas!$C$17,IF(E28<Premissas!$C$8,Premissas!$E$7,IF(E28<Premissas!$C$9,Premissas!$E$8,IF(E28<Premissas!$C$10,Premissas!$E$9,IF(E28<Premissas!$C$11,Premissas!$E$10,IF(E28<Premissas!$C$12,Premissas!$E$11,Premissas!$E$12))))))) | H28: =IF(OR(G28="",G28=0),0,G28/$C$6) -> 0 | J28: =IF(OR(G28="",I28=""),0,G28*I28) -> 0 | K28: =IF(OR(J28="",J28=0),0,J28/$C$6) -> 0
B29: TOTAL | I29: =SUM(I21:I28) -> 5 | J29: =SUM(J21:J28) -> 500 | K29: =SUM(K21:K28) -> 19.230769
B31: REGRAS
B32: 1. Indicador: FATOR = REALIZADO_ALLIN ÷ META_ALLIN (mesmo racional do operacional).
B33: 2. Todos os HCs Camisa 10/Apoio do CD recebem o mesmo valor (indicador coletivo).
B34: 3. Faixas e teto idênticos ao modelo operacional (aba Premissas).
B35: 4. Células amarelas = input. Demais = fórmulas.
B36: 5. Simulação CD1942: meta 470 | realizado 500 | fator 1,06 → faixa R$ 100 (exemplo com 5 HCs).
B37: 6. Preencha meta/realizado/qtd dos demais CDs para expandir a simulação de agosto.
B40: Projeção all in — o que acontece se o realizado mudar?
B41: Realizado simulado (editável) | C41: 500
B42: Meta (fix. CD1942) | C42: =C21 -> 470
B43: Fator simulado | C43: =IF(C42=0,"",C41/C42) -> 1.0638298
B44: Valor mensal/HC | C44: =IF(C43="","",MIN(Premissas!$C$17,IF(C43<Premissas!$C$8,Premissas!$E$7,IF(C43<Premissas!$C$9,Premissas!$E$8,IF(C43<Premissas!$C$10,Premissas!$E$9,IF(C43<Premissas!$C$11,Premissas!$E$10,IF(C43<Premissas!$C$12,Premissas!$E$11,Premissas!$E$12))))))) -> 100
B45: Valor diário/HC | C45: =IF(OR(C44="",C44=0),0,C44/$C$6) -> 3.8461538

Sheet Detalhe_Registro
A1: MES | B1: CD | C1: ATIVIDADE | D1: USUARIO | E1: COLABORADOR | F1: QUANTIDADE | G1: HORAS | H1: PRODUTIVIDADE | I1: META_ORIGINAL | J1: META_USADA | K1: META_PREENCHIDA | L1: EMPRESA_AJUSTADA | M1: FATOR | N1: VALOR_MENSAL | O1: VALOR_DIARIO
A2: 7 | B2: 409 | C2: ATIVIDADE OP. EMP. | D2: 182403 | E2: Reginaldo Alves Araujo | F2: 2377 | G2: 66.81 | H2: 36 | I2: 25 | J2: 25 | K2: NÃO | L2: GPA | M2: =IF(OR(J2="",J2<=0),"",H2/J2) -> 1.44 | N2: =IF(M2="","",IF(M2<Premissas!$C$8,Premissas!$E$7,IF(M2<Premissas!$C$9,Premissas!$E$8,IF(M2<Premissas!$C$10,Premissas!$E$9,IF(M2<Premissas!$C$11,Premissas!$E$10,IF(M2<Premissas!$C$12,Premissas!$E$11,Premissas!$E$12)))))) -> 350 | O2: =IF(OR(N2="",N2=0),0,N2/Premissas!$C$16) -> 13.461538
A3: 7 | B3: 409 | C3: RECEBIMENTO | D3: 250187 | E3: Marcio Da Silva Rodrigues | F3: 1518 | G3: 30.47 | H3: 50 | I3: 25 | J3: 25 | K3: NÃO | L3: GPA | M3: =IF(OR(J3="",J3<=0),"",H3/J3) -> 2 | N3: =IF(M3="","",IF(M3<Premissas!$C$8,Premissas!$E$7,IF(M3<Premissas!$C$9,Premissas!$E$8,IF(M3<Premissas!$C$10,Premissas!$E$9,IF(M3<Premissas!$C$11,Premissas!$E$10,IF(M3<Premissas!$C$12,Premissas!$E$11,Premissas!$E$12)))))) -> 750 | O3: =IF(OR(N3="",N3=0),0,N3/Premissas!$C$16) -> 28.846154
A4: 7 | B4: 409 | C4: CARREGAMENTO | D4: 250896 | E4: Hugo Clementino Nunes | F4: 272 | G4: 4.08 | H4: 67 | I4: 24 | J4: 24 | K4: NÃO | L4: GPA | M4: =IF(OR(J4="",J4<=0),"",H4/J4) -> 2.7916667 | N4: =IF(M4="","",IF(M4<Premissas!$C$8,Premissas!$E$7,IF(M4<Premissas!$C$9,Premissas!$E$8,IF(M4<Premissas!$C$10,Premissas!$E$9,IF(M4<Premissas!$C$11,Premissas!$E$10,IF(M4<Premissas!$C$12,Premissas!$E$11,Premissas!$E$12)))))) -> 750 | O4: =IF(OR(N4="",N4=0),0,N4/Premissas!$C$16) -> 28.846154
A5: 7 | B5: 409 | C5: PUXADA RECEB | D5: 250896 | E5: Hugo Clementino Nunes | F5: 318 | G5: 9.38 | H5: 34 | I5: 22 | J5: 22 | K5: NÃO | L5: GPA | M5: =IF(OR(J5="",J5<=0),"",H5/J5) -> 1.5454545 | N5: =IF(M5="","",IF(M5<Premissas!$C$8,Premissas!$E$7,IF(M5<Premissas!$C$9,Premissas!$E$8,IF(M5<Premissas!$C$10,Premissas!$E$9,IF(M5<Premissas!$C$11,Premissas!$E$10,IF(M5<Premissas!$C$12,Premissas!$E$11,Premissas!$E$12)))))) -> 350 | O5: =IF(OR(N5="",N5=0),0,N5/Premissas!$C$16) -> 13.461538
A6: 7 | B6: 409 | C6: RECEBIMENTO | D6: 250896 | E6: Hugo Clementino Nunes | F6: 187 | G6: 7.68 | H6: 24 | I6: 25 | J6: 25 | K6: NÃO | L6: GPA | M6: =IF(OR(J6="",J6<=0),"",H6/J6) -> 0.96 | N6: =IF(M6="","",IF(M6<Premissas!$C$8,Premissas!$E$7,IF(M6<Premissas!$C$9,Premissas!$E$8,IF(M6<Premissas!$C$10,Premissas!$E$9,IF(M6<Premissas!$C$11,Premissas!$E$10,IF(M6<Premissas!$C$12,Premissas!$E$11,Premissas!$E$12)))))) -> 0 | O6: =IF(OR(N6="",N6=0),0,N6/Premissas!$C$16) -> 0
A7: 7 | B7: 409 | C7: PUXADA RECEB | D7: 251239 | E7: Mauricio Rodrigues | F7: 124 | G7: 7.08 | H7: 18 | I7: 22 | J7: 22 | K7: NÃO | L7: GPA | M7: =IF(OR(J7="",J7<=0),"",H7/J7) -> 0.81818182 | N7: =IF(M7="","",IF(M7<Premissas!$C$8,Premissas!$E$7,IF(M7<Premissas!$C$9,Premissas!$E$8,IF(M7<Premissas!$C$10,Premissas!$E$9,IF(M7<Premissas!$C$11,Premissas!$E$10,IF(M7<Premissas!$C$12,Premissas!$E$11,Premissas!$E$12)))))) -> 0 | O7: =IF(OR(N7="",N7=0),0,N7/Premissas!$C$16) -> 0
A8: 7 | B8: 409 | C8: PUXADA RECEB | D8: 251240 | E8: Gildo Antonio Barbosa | F8: 38 | G8: 1.3 | H8: 29 | I8: 22 | J8: 22 | K8: NÃO | L8: GPA | M8: =IF(OR(J8="",J8<=0),"",H8/J8) -> 1.3181818 | N8: =IF(M8="","",IF(M8<Premissas!$C$8,Premissas!$E$7,IF(M8<Premissas!$C$9,Premissas!$E$8,IF(M8<Premissas!$C$10,Premissas!$E$9,IF(M8<Premissas!$C$11,Premissas!$E$10,IF(M8<Premissas!$C$12,Premissas!$E$11,Premissas!$E$12)))))) -> 200 | O8: =IF(OR(N8="",N8=0),0,N8/Premissas!$C$16) -> 7.6923077
A9: 7 | B9: 409 | C9: RECEBIMENTO | D9: 251240 | E9: Gildo Antonio Barbosa | F9: 3278 | G9: 39.72 | H9: 83 | I9: 25 | J9: 25 | K9: NÃO | L9: GPA | M9: =IF(OR(J9="",J9<=0),"",H9/J9) -> 3.32 | N9: =IF(M9="","",IF(M9<Premissas!$C$8,Premissas!$E$7,IF(M9<Premissas!$C$9,Premissas!$E$8,IF(M9<Premissas!$C$10,Premissas!$E$9,IF(M9<Premissas!$C$11,Premissas!$E$10,IF(M9<Premissas!$C$12,Premissas!$E$11,Premissas!$E$12)))))) -> 750 | O9: =IF(OR(N9="",N9=0),0,N9/Premissas!$C$16) -> 28.846154
A10: 7 | B10: 409 | C10: CARREGAMENTO | D10: 255199 | E10: Gilberton Santana De Moura | F10: 344 | G10: 7.68 | H10: 45 | I10: 24 | J10: 24 | K10: NÃO | L10: GPA | M10: =IF(OR(J10="",J10<=0),"",H10/J10) -> 1.875 | N10: =IF(M10="","",IF(M10<Premissas!$C$8,Premissas!$E$7,IF(M10<Premissas!$C$9,Premissas!$E$8,IF(M10<Premissas!$C$10,Premissas!$E$9,IF(M10<Premissas!$C$11,Premissas!$E$10,IF(M10<Premissas!$C$12,Premissas!$E$11,Premissas!$E$12)))))) -> 500 | O10: =IF(OR(N10="",N10=0),0,N10/Premissas!$C$16) -> 19.230769
A11: 7 | B11: 409 | C11: ATIVIDADE OP. EMP. | D11: 264318 | E11: Flavio Soares Da Silva | F11: 2828 | G11: 66.5 | H11: 43 | I11: 25 | J11: 25 | K11: NÃO | L11: GPA | M11: =IF(OR(J11="",J11<=0),"",H11/J11) -> 1.72 | N11: =IF(M11="","",IF(M11<Premissas!$C$8,Premissas!$E$7,IF(M11<Premissas!$C$9,Premissas!$E$8,IF(M11<Premissas!$C$10,Premissas!$E$9,IF(M11<Premissas!$C$11,Premissas!$E$10,IF(M11<Premissas!$C$12,Premissas!$E$11,Premissas!$E$12)))))) -> 500 | O11: =IF(OR(N11="",N11=0),0,N11/Premissas!$C$16) -> 19.230769
A12: 7 | B12: 409 | C12: ATIVIDADE OP. EMP. | D12: 264446 | E12: HUMBERTO DE ANDRADE SILVA | F12: 1857 | G12: 46.24 | H12: 40 | I12: 25 | J12: 25 | K12: NÃO | L12: GPA | M12: =IF(OR(J12="",J12<=0),"",H12/J12) -> 1.6 | N12: =IF(M12="","",IF(M12<Premissas!$C$8,Premissas!$E$7,IF(M12<Premissas!$C$9,Premissas!$E$8,IF(M12<Premissas!$C$10,Premissas!$E$9,IF(M12<Premissas!$C$11,Premissas!$E$10,IF(M12<Premissas!$C$12,Premissas!$E$11,Premissas!$E$12)))))) -> 500 | O12: =IF(OR(N12="",N12=0),0,N12/Premissas!$C$16) -> 19.230769
A13: 7 | B13: 409 | C13: ATIVIDADE OP. EMP. | D13: 265139 | E13: Ronieles Junior Vasconcelos | F13: 1507 | G13: 52.63 | H13: 29 | I13: 25 | J13: 25 | K13: NÃO | L13: GPA | M13: =IF(OR(J13="",J13<=0),"",H13/J13) -> 1.16 | N13: =IF(M13="","",IF(M13<Premissas!$C$8,Premissas!$E$7,IF(M13<Premissas!$C$9,Premissas!$E$8,IF(M13<Premissas!$C$10,Premissas!$E$9,IF(M13<Premissas!$C$11,Premissas!$E$10,IF(M13<Premissas!$C$12,Premissas!$E$11,Premissas!$E$12)))))) -> 100 | O13: =IF(OR(N13="",N13=0),0,N13/Premissas!$C$16) -> 3.8461538
... A362: 7 | B362: 1974 | C362: ATIVIDADE OP. EMP. | D362: 143573 | E362: ALEXANDRE GLEYSON GOMES TEIXEIRA | F362: 51 | G362: 1.31 | H362: 39 | I362: 9 | J362: 9 | K362: NÃO | L362: GPA | M362: =IF(OR(J362="",J362<=0),"",H362/J362) -> 4.3333333 | N362: =IF(M362="","",IF(M362<Premissas!$C$8,Premissas!$E$7,IF(M362<Premissas!$C$9,Premissas!$E$8,IF(M362<Premissas!$C$10,Premissas!$E$9,IF(M362<Premissas!$C$11,Premissas!$E$10,IF(M362<Premissas!$C$12,Premissas!$E$11,Premissas!$E$12)))))) -> 750 | O362: =IF(OR(N362="",N362=0),0,N362/Premissas!$C$16) -> 28.846154
A363: 7 | B363: 1974 | C363: CARREGAMENTO | D363: 149952 | E363: RONALD NUNES DOS SANTOS | F363: 23 | G363: 1.21 | H363: 19 | J363: 22 | K363: SIM | L363: GPA | M363: =IF(OR(J363="",J363<=0),"",H363/J363) -> 0.86363636 | N363: =IF(M363="","",IF(M363<Premissas!$C$8,Premissas!$E$7,IF(M363<Premissas!$C$9,Premissas!$E$8,IF(M363<Premissas!$C$10,Premissas!$E$9,IF(M363<Premissas!$C$11,Premissas!$E$10,IF(M363<Premissas!$C$12,Premissas!$E$11,Premissas!$E$12)))))) -> 0 | O363: =IF(OR(N363="",N363=0),0,N363/Premissas!$C$16) -> 0
A364: 7 | B364: 1974 | C364: PUXADA RECEB | D364: 149952 | E364: RONALD NUNES DOS SANTOS | F364: 95 | G364: 2.7 | H364: 35 | J364: 16 | K364: SIM | L364: GPA | M364: =IF(OR(J364="",J364<=0),"",H364/J364) -> 2.1875 | N364: =IF(M364="","",IF(M364<Premissas!$C$8,Premissas!$E$7,IF(M364<Premissas!$C$9,Premissas!$E$8,IF(M364<Premissas!$C$10,Premissas!$E$9,IF(M364<Premissas!$C$11,Premissas!$E$10,IF(M364<Premissas!$C$12,Premissas!$E$11,Premissas!$E$12)))))) -> 750 | O364: =IF(OR(N364="",N364=0),0,N364/Premissas!$C$16) -> 28.846154
A365: 7 | B365: 1974 | C365: RECEBIMENTO | D365: 149952 | E365: RONALD NUNES DOS SANTOS | F365: 357 | G365: 6.48 | H365: 55 | I365: 41 | J365: 41 | K365: NÃO | L365: GPA | M365: =IF(OR(J365="",J365<=0),"",H365/J365) -> 1.3414634 | N365: =IF(M365="","",IF(M365<Premissas!$C$8,Premissas!$E$7,IF(M365<Premissas!$C$9,Premissas!$E$8,IF(M365<Premissas!$C$10,Premissas!$E$9,IF(M365<Premissas!$C$11,Premissas!$E$10,IF(M365<Premissas!$C$12,Premissas!$E$11,Premissas!$E$12)))))) -> 200 | O365: =IF(OR(N365="",N365=0),0,N365/Premissas!$C$16) -> 7.6923077
A366: 7 | B366: 1974 | C366: ATIVIDADE OP. EMP. | D366: 157110 | E366: FRANCISCO JEAN MOURA | F366: 2623 | G366: 101.11 | H366: 26 | I366: 9 | J366: 9 | K366: NÃO | L366: GPA | M366: =IF(OR(J366="",J366<=0),"",H366/J366) -> 2.8888889 | N366: =IF(M366="","",IF(M366<Premissas!$C$8,Premissas!$E$7,IF(M366<Premissas!$C$9,Premissas!$E$8,IF(M366<Premissas!$C$10,Premissas!$E$9,IF(M366<Premissas!$C$11,Premissas!$E$10,IF(M366<Premissas!$C$12,Premissas!$E$11,Premissas!$E$12)))))) -> 750 | O366: =IF(OR(N366="",N366=0),0,N366/Premissas!$C$16) -> 28.846154
A367: 7 | B367: 1974 | C367: ATIVIDADE OP. EMP. | D367: 157789 | E367: FRANCISCO DAS CHAGAS ALVES RODRIGUES | F367: 1783 | G367: 51.71 | H367: 34 | I367: 9 | J367: 9 | K367: NÃO | L367: GPA | M367: =IF(OR(J367="",J367<=0),"",H367/J367) -> 3.7777778 | N367: =IF(M367="","",IF(M367<Premissas!$C$8,Premissas!$E$7,IF(M367<Premissas!$C$9,Premissas!$E$8,IF(M367<Premissas!$C$10,Premissas!$E$9,IF(M367<Premissas!$C$11,Premissas!$E$10,IF(M367<Premissas!$C$12,Premissas!$E$11,Premissas!$E$12)))))) -> 750 | O367: =IF(OR(N367="",N367=0),0,N367/Premissas!$C$16) -> 28.846154
A368: 7 | B368: 1974 | C368: ATIVIDADE OP. EMP. | D368: 286911 | E368: ANTONIO CARLOS DOS SANTOS SOUZA | F368: 2222 | G368: 65.97 | H368: 34 | I368: 9 | J368: 9 | K368: NÃO | L368: GPA | M368: =IF(OR(J368="",J368<=0),"",H368/J368) -> 3.7777778 | N368: =IF(M368="","",IF(M368<Premissas!$C$8,Premissas!$E$7,IF(M368<Premissas!$C$9,Premissas!$E$8,IF(M368<Premissas!$C$10,Premissas!$E$9,IF(M368<Premissas!$C$11,Premissas!$E$10,IF(M368<Premissas!$C$12,Premissas!$E$11,Premissas!$E$12)))))) -> 750 | O368: =IF(OR(N368="",N368=0),0,N368/Premissas!$C$16) -> 28.846154
A369: 7 | B369: 1974 | C369: RECEBIMENTO | D369: 2984822 | E369: SAMIA SOUZA NOGUEIRA | F369: 2 | G369: 0.02 | H369: 100 | I369: 41 | J369: 41 | K369: NÃO | L369: GPA | M369: =IF(OR(J369="",J369<=0),"",H369/J369) -> 2.4390244 | N369: =IF(M369="","",IF(M369<Premissas!$C$8,Premissas!$E$7,IF(M369<Premissas!$C$9,Premissas!$E$8,IF(M369<Premissas!$C$10,Premissas!$E$9,IF(M369<Premissas!$C$11,Premissas!$E$10,IF(M369<Premissas!$C$12,Premissas!$E$11,Premissas!$E$12)))))) -> 750 | O369: =IF(OR(N369="",N369=0),0,N369/Premissas!$C$16) -> 28.846154
A370: 7 | B370: 1974 | C370: ATIVIDADE OP. EMP. | D370: 316536 | E370: JOSE HORMANDO SOARES DOS SANTOS | F370: 2224 | G370: 68.12 | H370: 33 | I370: 9 | J370: 9 | K370: NÃO | L370: GPA | M370: =IF(OR(J370="",J370<=0),"",H370/J370) -> 3.6666667 | N370: =IF(M370="","",IF(M370<Premissas!$C$8,Premissas!$E$7,IF(M370<Premissas!$C$9,Premissas!$E$8,IF(M370<Premissas!$C$10,Premissas!$E$9,IF(M370<Premissas!$C$11,Premissas!$E$10,IF(M370<Premissas!$C$12,Premissas!$E$11,Premissas!$E$12)))))) -> 750 | O370: =IF(OR(N370="",N370=0),0,N370/Premissas!$C$16) -> 28.846154
A371: 7 | B371: 1974 | C371: CARREGAMENTO | D371: 365615 | E371: FIRMINO NETO DE SOUSA SILVA | F371: 159 | G371: 7.05 | H371: 23 | J371: 22 | K371: SIM | L371: GPA | M371: =IF(OR(J371="",J371<=0),"",H371/J371) -> 1.0454545 | N371: =IF(M371="","",IF(M371<Premissas!$C$8,Premissas!$E$7,IF(M371<Premissas!$C$9,Premissas!$E$8,IF(M371<Premissas!$C$10,Premissas!$E$9,IF(M371<Premissas!$C$11,Premissas!$E$10,IF(M371<Premissas!$C$12,Premissas!$E$11,Premissas!$E$12)))))) -> 100 | O371: =IF(OR(N371="",N371=0),0,N371/Premissas!$C$16) -> 3.8461538
A372: 7 | B372: 1974 | C372: PUXADA RECEB | D372: 365615 | E372: FIRMINO NETO DE SOUSA SILVA | F372: 49 | G372: 3.68 | H372: 13 | J372: 16 | K372: SIM | L372: GPA | M372: =IF(OR(J372="",J372<=0),"",H372/J372) -> 0.8125 | N372: =IF(M372="","",IF(M372<Premissas!$C$8,Premissas!$E$7,IF(M372<Premissas!$C$9,Premissas!$E$8,IF(M372<Premissas!$C$10,Premissas!$E$9,IF(M372<Premissas!$C$11,Premissas!$E$10,IF(M372<Premissas!$C$12,Premissas!$E$11,Premissas!$E$12)))))) -> 0 | O372: =IF(OR(N372="",N372=0),0,N372/Premissas!$C$16) -> 0
A373: 7 | B373: 1974 | C373: RECEBIMENTO | D373: 365615 | E373: FIRMINO NETO DE SOUSA SILVA | F373: 2251 | G373: 33.25 | H373: 68 | I373: 41 | J373: 41 | K373: NÃO | L373: GPA | M373: =IF(OR(J373="",J373<=0),"",H373/J373) -> 1.6585366 | N373: =IF(M373="","",IF(M373<Premissas!$C$8,Premissas!$E$7,IF(M373<Premissas!$C$9,Premissas!$E$8,IF(M373<Premissas!$C$10,Premissas!$E$9,IF(M373<Premissas!$C$11,Premissas!$E$10,IF(M373<Premissas!$C$12,Premissas!$E$11,Premissas!$E$12)))))) -> 500 | O373: =IF(OR(N373="",N373=0),0,N373/Premissas!$C$16) -> 19.230769
A374: 7 | B374: 1974 | C374: ATIVIDADE OP. EMP. | D374: 5425590 | E374: Thiago Igor Soares Vieira | F374: 602 | G374: 21.59 | H374: 28 | I374: 9 | J374: 9 | K374: NÃO | L374: GPA | M374: =IF(OR(J374="",J374<=0),"",H374/J374) -> 3.1111111 | N374: =IF(M374="","",IF(M374<Premissas!$C$8,Premissas!$E$7,IF(M374<Premissas!$C$9,Premissas!$E$8,IF(M374<Premissas!$C$10,Premissas!$E$9,IF(M374<Premissas!$C$11,Premissas!$E$10,IF(M374<Premissas!$C$12,Premissas!$E$11,Premissas!$E$12)))))) -> 750 | O374: =IF(OR(N374="",N374=0),0,N374/Premissas!$C$16) -> 28.846154
A375: 7 | B375: 1974 | C375: CARREGAMENTO | D375: 5426251 | E375: Alisson Vitor Vieira Diniz | F375: 441 | G375: 8.54 | H375: 52 | J375: 22 | K375: SIM | L375: GPA | M375: =IF(OR(J375="",J375<=0),"",H375/J375) -> 2.3636364 | N375: =IF(M375="","",IF(M375<Premissas!$C$8,Premissas!$E$7,IF(M375<Premissas!$C$9,Premissas!$E$8,IF(M375<Premissas!$C$10,Premissas!$E$9,IF(M375<Premissas!$C$11,Premissas!$E$10,IF(M375<Premissas!$C$12,Premissas!$E$11,Premissas!$E$12)))))) -> 750 | O375: =IF(OR(N375="",N375=0),0,N375/Premissas!$C$16) -> 28.846154
A376: 7 | B376: 1974 | C376: PUXADA RECEB | D376: 5426251 | E376: Alisson Vitor Vieira Diniz | F376: 159 | G376: 7.56 | H376: 21 | J376: 16 | K376: SIM | L376: GPA | M376: =IF(OR(J376="",J376<=0),"",H376/J376) -> 1.3125 | N376: =IF(M376="","",IF(M376<Premissas!$C$8,Premissas!$E$7,IF(M376<Premissas!$C$9,Premissas!$E$8,IF(M376<Premissas!$C$10,Premissas!$E$9,IF(M376<Premissas!$C$11,Premissas!$E$10,IF(M376<Premissas!$C$12,Premissas!$E$11,Premissas!$E$12)))))) -> 200 | O376: =IF(OR(N376="",N376=0),0,N376/Premissas!$C$16) -> 7.6923077
A377: 7 | B377: 1974 | C377: RECEBIMENTO | D377: 5426251 | E377: Alisson Vitor Vieira Diniz | F377: 963 | G377: 27.36 | H377: 35 | I377: 41 | J377: 41 | K377: NÃO | L377: GPA | M377: =IF(OR(J377="",J377<=0),"",H377/J377) -> 0.85365854 | N377: =IF(M377="","",IF(M377<Premissas!$C$8,Premissas!$E$7,IF(M377<Premissas!$C$9,Premissas!$E$8,IF(M377<Premissas!$C$10,Premissas!$E$9,IF(M377<Premissas!$C$11,Premissas!$E$10,IF(M377<Premissas!$C$12,Premissas!$E$11,Premissas!$E$12)))))) -> 0 | O377: =IF(OR(N377="",N377=0),0,N377/Premissas!$C$16) -> 0
A378: 7 | B378: 1974 | C378: CARREGAMENTO | D378: 5440050 | E378: Daniel Diogo Moraes | F378: 1551 | G378: 19.29 | H378: 80 | J378: 22 | K378: SIM | L378: GPA | M378: =IF(OR(J378="",J378<=0),"",H378/J378) -> 3.6363636 | N378: =IF(M378="","",IF(M378<Premissas!$C$8,Premissas!$E$7,IF(M378<Premissas!$C$9,Premissas!$E$8,IF(M378<Premissas!$C$10,Premissas!$E$9,IF(M378<Premissas!$C$11,Premissas!$E$10,IF(M378<Premissas!$C$12,Premissas!$E$11,Premissas!$E$12)))))) -> 750 | O378: =IF(OR(N378="",N378=0),0,N378/Premissas!$C$16) -> 28.846154
A379: 7 | B379: 1974 | C379: PUXADA RECEB | D379: 5440050 | E379: Daniel Diogo Moraes | F379: 33 | G379: 1.05 | H379: 31 | J379: 16 | K379: SIM | L379: GPA | M379: =IF(OR(J379="",J379<=0),"",H379/J379) -> 1.9375 | N379: =IF(M379="","",IF(M379<Premissas!$C$8,Premissas!$E$7,IF(M379<Premissas!$C$9,Premissas!$E$8,IF(M379<Premissas!$C$10,Premissas!$E$9,IF(M379<Premissas!$C$11,Premissas!$E$10,IF(M379<Premissas!$C$12,Premissas!$E$11,Premissas!$E$12)))))) -> 750 | O379: =IF(OR(N379="",N379=0),0,N379/Premissas!$C$16) -> 28.846154
A380: 7 | B380: 1974 | C380: RECEBIMENTO | D380: 5440050 | E380: Daniel Diogo Moraes | F380: 140 | G380: 1.44 | H380: 97 | I380: 41 | J380: 41 | K380: NÃO | L380: GPA | M380: =IF(OR(J380="",J380<=0),"",H380/J380) -> 2.3658537 | N380: =IF(M380="","",IF(M380<Premissas!$C$8,Premissas!$E$7,IF(M380<Premissas!$C$9,Premissas!$E$8,IF(M380<Premissas!$C$10,Premissas!$E$9,IF(M380<Premissas!$C$11,Premissas!$E$10,IF(M380<Premissas!$C$12,Premissas!$E$11,Premissas!$E$12)))))) -> 750 | O380: =IF(OR(N380="",N380=0),0,N380/Premissas!$C$16) -> 28.846154
A381: 7 | B381: 1974 | C381: PUXADA RECEB | D381: 5440114 | E381: Antonio Lucas De Oliveira Matos | F381: 90 | G381: 3.08 | H381: 29 | J381: 16 | K381: SIM | L381: GPA | M381: =IF(OR(J381="",J381<=0),"",H381/J381) -> 1.8125 | N381: =IF(M381="","",IF(M381<Premissas!$C$8,Premissas!$E$7,IF(M381<Premissas!$C$9,Premissas!$E$8,IF(M381<Premissas!$C$10,Premissas!$E$9,IF(M381<Premissas!$C$11,Premissas!$E$10,IF(M381<Premissas!$C$12,Premissas!$E$11,Premissas!$E$12)))))) -> 500 | O381: =IF(OR(N381="",N381=0),0,N381/Premissas!$C$16) -> 19.230769
A382: 7 | B382: 1974 | C382: CARREGAMENTO | D382: 5441927 | E382: Cicero Manoel Da Silva | F382: 405 | G382: 2.44 | H382: 166 | J382: 22 | K382: SIM | L382: GPA | M382: =IF(OR(J382="",J382<=0),"",H382/J382) -> 7.5454545 | N382: =IF(M382="","",IF(M382<Premissas!$C$8,Premissas!$E$7,IF(M382<Premissas!$C$9,Premissas!$E$8,IF(M382<Premissas!$C$10,Premissas!$E$9,IF(M382<Premissas!$C$11,Premissas!$E$10,IF(M382<Premissas!$C$12,Premissas!$E$11,Premissas!$E$12)))))) -> 750 | O382: =IF(OR(N382="",N382=0),0,N382/Premissas!$C$16) -> 28.846154
A383: 7 | B383: 1974 | C383: PUXADA RECEB | D383: 5441927 | E383: Cicero Manoel Da Silva | F383: 286 | G383: 8.33 | H383: 34 | J383: 16 | K383: SIM | L383: GPA | M383: =IF(OR(J383="",J383<=0),"",H383/J383) -> 2.125 | N383: =IF(M383="","",IF(M383<Premissas!$C$8,Premissas!$E$7,IF(M383<Premissas!$C$9,Premissas!$E$8,IF(M383<Premissas!$C$10,Premissas!$E$9,IF(M383<Premissas!$C$11,Premissas!$E$10,IF(M383<Premissas!$C$12,Premissas!$E$11,Premissas!$E$12)))))) -> 750 | O383: =IF(OR(N383="",N383=0),0,N383/Premissas!$C$16) -> 28.846154
A384: 7 | B384: 1974 | C384: RECEBIMENTO | D384: 5441927 | E384: Cicero Manoel Da Silva | F384: 1596 | G384: 31.71 | H384: 50 | I384: 41 | J384: 41 | K384: NÃO | L384: GPA | M384: =IF(OR(J384="",J384<=0),"",H384/J384) -> 1.2195122 | N384: =IF(M384="","",IF(M384<Premissas!$C$8,Premissas!$E$7,IF(M384<Premissas!$C$9,Premissas!$E$8,IF(M384<Premissas!$C$10,Premissas!$E$9,IF(M384<Premissas!$C$11,Premissas!$E$10,IF(M384<Premissas!$C$12,Premissas!$E$11,Premissas!$E$12)))))) -> 200 | O384: =IF(OR(N384="",N384=0),0,N384/Premissas!$C$16) -> 7.6923077
A385: 7 | B385: 1974 | C385: ATIVIDADE OP. EMP. | D385: 5443148 | E385: Danilson Paulino De Sousa | F385: 1938 | G385: 74.34 | H385: 26 | I385: 9 | J385: 9 | K385: NÃO | L385: GPA | M385: =IF(OR(J385="",J385<=0),"",H385/J385) -> 2.8888889 | N385: =IF(M385="","",IF(M385<Premissas!$C$8,Premissas!$E$7,IF(M385<Premissas!$C$9,Premissas!$E$8,IF(M385<Premissas!$C$10,Premissas!$E$9,IF(M385<Premissas!$C$11,Premissas!$E$10,IF(M385<Premissas!$C$12,Premissas!$E$11,Premissas!$E$12)))))) -> 750 | O385: =IF(OR(N385="",N385=0),0,N385/Premissas!$C$16) -> 28.846154
A386: 7 | B386: 1974 | C386: PUXADA RECEB | D386: 5443571 | E386: Isaac Marques Do Nascimento | F386: 67 | G386: 2.31 | H386: 29 | J386: 16 | K386: SIM | L386: GPA | M386: =IF(OR(J386="",J386<=0),"",H386/J386) -> 1.8125 | N386: =IF(M386="","",IF(M386<Premissas!$C$8,Premissas!$E$7,IF(M386<Premissas!$C$9,Premissas!$E$8,IF(M386<Premissas!$C$10,Premissas!$E$9,IF(M386<Premissas!$C$11,Premissas!$E$10,IF(M386<Premissas!$C$12,Premissas!$E$11,Premissas!$E$12)))))) -> 500 | O386: =IF(OR(N386="",N386=0),0,N386/Premissas!$C$16) -> 19.230769
A387: 7 | B387: 1974 | C387: PUXADA RECEB | D387: 5451671 | E387: Fabio Mota De Sousa | F387: 801 | G387: 35.48 | H387: 23 | J387: 16 | K387: SIM | L387: GPA | M387: =IF(OR(J387="",J387<=0),"",H387/J387) -> 1.4375 | N387: =IF(M387="","",IF(M387<Premissas!$C$8,Premissas!$E$7,IF(M387<Premissas!$C$9,Premissas!$E$8,IF(M387<Premissas!$C$10,Premissas!$E$9,IF(M387<Premissas!$C$11,Premissas!$E$10,IF(M387<Premissas!$C$12,Premissas!$E$11,Premissas!$E$12)))))) -> 350 | O387: =IF(OR(N387="",N387=0),0,N387/Premissas!$C$16) -> 13.461538
A388: 7 | B388: 1974 | C388: CARREGAMENTO | D388: 5464170 | E388: Cicero Ricardo Da Silva | F388: 45 | G388: 1.22 | H388: 37 | J388: 22 | K388: SIM | L388: GPA | M388: =IF(OR(J388="",J388<=0),"",H388/J388) -> 1.6818182 | N388: =IF(M388="","",IF(M388<Premissas!$C$8,Premissas!$E$7,IF(M388<Premissas!$C$9,Premissas!$E$8,IF(M388<Premissas!$C$10,Premissas!$E$9,IF(M388<Premissas!$C$11,Premissas!$E$10,IF(M388<Premissas!$C$12,Premissas!$E$11,Premissas!$E$12)))))) -> 500 | O388: =IF(OR(N388="",N388=0),0,N388/Premissas!$C$16) -> 19.230769
...

Sheet Consolidado_HC
A1: MES | B1: USUARIO | C1: COLABORADOR | D1: CD_PRINCIPAL | E1: ATIVIDADES | F1: N_REG | G1: MELHOR_FATOR | H1: FATOR_MEDIO | I1: QTD_TOTAL | J1: HORAS | K1: FAIXA | L1: VALOR_MENSAL | M1: VALOR_DIARIO | N1: NO_TETO
A2: 7 | B2: 5439698 | C2: GABRIEL RODRIGUES DE VASCONCELOS | D2: 1942 | E2: PUXADA RECEB | F2: =COUNTIFS(Detalhe_Registro!$A:$A,A2,Detalhe_Registro!$D:$D,B2) -> 1 | G2: 1.125 | H2: 1.125 | I2: =SUMIFS(Detalhe_Registro!$F:$F,Detalhe_Registro!$A:$A,A2,Detalhe_Registro!$D:$D,B2) -> 179 | J2: =SUMIFS(Detalhe_Registro!$G:$G,Detalhe_Registro!$A:$A,A2,Detalhe_Registro!$D:$D,B2) -> 10.14 | K2: =IF(G2="","",IF(G2<Premissas!$C$8,"< 1,00",IF(G2<Premissas!$C$9,"1,00 – 1,19",IF(G2<Premissas!$C$10,"1,20 – 1,39",IF(G2<Premissas!$C$11,"1,40 – 1,59",IF(G2<Premissas!$C$12,"1,60 – 1,99","≥ 2,00")))))) -> 1,00 – 1,19 | L2: =IF(G2="","",MIN(Premissas!$C$17,IF(G2<Premissas!$C$8,Premissas!$E$7,IF(G2<Premissas!$C$9,Premissas!$E$8,IF(G2<Premissas!$C$10,Premissas!$E$9,IF(G2<Premissas!$C$11,Premissas!$E$10,IF(G2<Premissas!$C$12,Premissas!$E$11,Premissas!$E$12))))))) -> 100 | M2: =IF(OR(L2="",L2=0),0,L2/Premissas!$C$16) -> 3.8461538 | N2: =IF(L2>=Premissas!$C$17,"SIM","NÃO") -> NÃO
A3: 7 | B3: 570046 | C3: ADRIANO PEREIRA DE SOUSA | D3: 1942 | E3: RECEBIMENTO | F3: =COUNTIFS(Detalhe_Registro!$A:$A,A3,Detalhe_Registro!$D:$D,B3) -> 1 | G3: 1.588235 | H3: 1.588235 | I3: =SUMIFS(Detalhe_Registro!$F:$F,Detalhe_Registro!$A:$A,A3,Detalhe_Registro!$D:$D,B3) -> 701 | J3: =SUMIFS(Detalhe_Registro!$G:$G,Detalhe_Registro!$A:$A,A3,Detalhe_Registro!$D:$D,B3) -> 25.59 | K3: =IF(G3="","",IF(G3<Premissas!$C$8,"< 1,00",IF(G3<Premissas!$C$9,"1,00 – 1,19",IF(G3<Premissas!$C$10,"1,20 – 1,39",IF(G3<Premissas!$C$11,"1,40 – 1,59",IF(G3<Premissas!$C$12,"1,60 – 1,99","≥ 2,00")))))) -> 1,40 – 1,59 | L3: =IF(G3="","",MIN(Premissas!$C$17,IF(G3<Premissas!$C$8,Premissas!$E$7,IF(G3<Premissas!$C$9,Premissas!$E$8,IF(G3<Premissas!$C$10,Premissas!$E$9,IF(G3<Premissas!$C$11,Premissas!$E$10,IF(G3<Premissas!$C$12,Premissas!$E$11,Premissas!$E$12))))))) -> 350 | M3: =IF(OR(L3="",L3=0),0,L3/Premissas!$C$16) -> 13.461538 | N3: =IF(L3>=Premissas!$C$17,"SIM","NÃO") -> NÃO
A4: 7 | B4: 696054 | C4: AILTON MANGUEIRA DE ARAUJO | D4: 1942 | E4: ATIVIDADE OP. EMP. | F4: =COUNTIFS(Detalhe_Registro!$A:$A,A4,Detalhe_Registro!$D:$D,B4) -> 1 | G4: 1.85 | H4: 1.85 | I4: =SUMIFS(Detalhe_Registro!$F:$F,Detalhe_Registro!$A:$A,A4,Detalhe_Registro!$D:$D,B4) -> 1948 | J4: =SUMIFS(Detalhe_Registro!$G:$G,Detalhe_Registro!$A:$A,A4,Detalhe_Registro!$D:$D,B4) -> 52.62 | K4: =IF(G4="","",IF(G4<Premissas!$C$8,"< 1,00",IF(G4<Premissas!$C$9,"1,00 – 1,19",IF(G4<Premissas!$C$10,"1,20 – 1,39",IF(G4<Premissas!$C$11,"1,40 – 1,59",IF(G4<Premissas!$C$12,"1,60 – 1,99","≥ 2,00")))))) -> 1,60 – 1,99 | L4: =IF(G4="","",MIN(Premissas!$C$17,IF(G4<Premissas!$C$8,Premissas!$E$7,IF(G4<Premissas!$C$9,Premissas!$E$8,IF(G4<Premissas!$C$10,Premissas!$E$9,IF(G4<Premissas!$C$11,Premissas!$E$10,IF(G4<Premissas!$C$12,Premissas!$E$11,Premissas!$E$12))))))) -> 500 | M4: =IF(OR(L4="",L4=0),0,L4/Premissas!$C$16) -> 19.230769 | N4: =IF(L4>=Premissas!$C$17,"SIM","NÃO") -> NÃO
A5: 7 | B5: 687013 | C5: ALESSANDRO DE SOUSA BINA | D5: 1942 | E5: CARREGAMENTO | F5: =COUNTIFS(Detalhe_Registro!$A:$A,A5,Detalhe_Registro!$D:$D,B5) -> 1 | G5: 11.863636 | H5: 11.863636 | I5: =SUMIFS(Detalhe_Registro!$F:$F,Detalhe_Registro!$A:$A,A5,Detalhe_Registro!$D:$D,B5) -> 120 | J5: =SUMIFS(Detalhe_Registro!$G:$G,Detalhe_Registro!$A:$A,A5,Detalhe_Registro!$D:$D,B5) -> 0.46 | K5: =IF(G5="","",IF(G5<Premissas!$C$8,"< 1,00",IF(G5<Premissas!$C$9,"1,00 – 1,19",IF(G5<Premissas!$C$10,"1,20 – 1,39",IF(G5<Premissas!$C$11,"1,40 – 1,59",IF(G5<Premissas!$C$12,"1,60 – 1,99","≥ 2,00")))))) -> ≥ 2,00 | L5: =IF(G5="","",MIN(Premissas!$C$17,IF(G5<Premissas!$C$8,Premissas!$E$7,IF(G5<Premissas!$C$9,Premissas!$E$8,IF(G5<Premissas!$C$10,Premissas!$E$9,IF(G5<Premissas!$C$11,Premissas!$E$10,IF(G5<Premissas!$C$12,Premissas!$E$11,Premissas!$E$12))))))) -> 750 | M5: =IF(OR(L5="",L5=0),0,L5/Premissas!$C$16) -> 28.846154 | N5: =IF(L5>=Premissas!$C$17,"SIM","NÃO") -> SIM
A6: 7 | B6: 5432979 | C6: ALEXANDRE FERREIRA | D6: 1942 | E6: PUXADA RECEB | F6: =COUNTIFS(Detalhe_Registro!$A:$A,A6,Detalhe_Registro!$D:$D,B6) -> 1 | G6: 0.5 | H6: 0.5 | I6: =SUMIFS(Detalhe_Registro!$F:$F,Detalhe_Registro!$A:$A,A6,Detalhe_Registro!$D:$D,B6) -> 188 | J6: =SUMIFS(Detalhe_Registro!$G:$G,Detalhe_Registro!$A:$A,A6,Detalhe_Registro!$D:$D,B6) -> 24.66 | K6: =IF(G6="","",IF(G6<Premissas!$C$8,"< 1,00",IF(G6<Premissas!$C$9,"1,00 – 1,19",IF(G6<Premissas!$C$10,"1,20 – 1,39",IF(G6<Premissas!$C$11,"1,40 – 1,59",IF(G6<Premissas!$C$12,"1,60 – 1,99","≥ 2,00")))))) -> < 1,00 | L6: =IF(G6="","",MIN(Premissas!$C$17,IF(G6<Premissas!$C$8,Premissas!$E$7,IF(G6<Premissas!$C$9,Premissas!$E$8,IF(G6<Premissas!$C$10,Premissas!$E$9,IF(G6<Premissas!$C$11,Premissas!$E$10,IF(G6<Premissas!$C$12,Premissas!$E$11,Premissas!$E$12))))))) -> 0 | M6: =IF(OR(L6="",L6=0),0,L6/Premissas!$C$16) -> 0 | N6: =IF(L6>=Premissas!$C$17,"SIM","NÃO") -> NÃO
A7: 7 | B7: 5227321 | C7: ANILTON APARECIDO DE CAMPOS | D7: 1942 | E7: CARREGAMENTO | F7: =COUNTIFS(Detalhe_Registro!$A:$A,A7,Detalhe_Registro!$D:$D,B7) -> 1 | G7: 1.863636 | H7: 1.863636 | I7: =SUMIFS(Detalhe_Registro!$F:$F,Detalhe_Registro!$A:$A,A7,Detalhe_Registro!$D:$D,B7) -> 1263 | J7: =SUMIFS(Detalhe_Registro!$G:$G,Detalhe_Registro!$A:$A,A7,Detalhe_Registro!$D:$D,B7) -> 30.72 | K7: =IF(G7="","",IF(G7<Premissas!$C$8,"< 1,00",IF(G7<Premissas!$C$9,"1,00 – 1,19",IF(G7<Premissas!$C$10,"1,20 – 1,39",IF(G7<Premissas!$C$11,"1,40 – 1,59",IF(G7<Premissas!$C$12,"1,60 – 1,99","≥ 2,00")))))) -> 1,60 – 1,99 | L7: =IF(G7="","",MIN(Premissas!$C$17,IF(G7<Premissas!$C$8,Premissas!$E$7,IF(G7<Premissas!$C$9,Premissas!$E$8,IF(G7<Premissas!$C$10,Premissas!$E$9,IF(G7<Premissas!$C$11,Premissas!$E$10,IF(G7<Premissas!$C$12,Premissas!$E$11,Premissas!$E$12))))))) -> 500 | M7: =IF(OR(L7="",L7=0),0,L7/Premissas!$C$16) -> 19.230769 | N7: =IF(L7>=Premissas!$C$17,"SIM","NÃO") -> NÃO
A8: 7 | B8: 587354 | C8: ARLINDO CARDOSO DA SILVA JUNIOR | D8: 1942 | E8: ATIVIDADE OP. EMP. | F8: =COUNTIFS(Detalhe_Registro!$A:$A,A8,Detalhe_Registro!$D:$D,B8) -> 1 | G8: 1.1 | H8: 1.1 | I8: =SUMIFS(Detalhe_Registro!$F:$F,Detalhe_Registro!$A:$A,A8,Detalhe_Registro!$D:$D,B8) -> 1398 | J8: =SUMIFS(Detalhe_Registro!$G:$G,Detalhe_Registro!$A:$A,A8,Detalhe_Registro!$D:$D,B8) -> 64.09 | K8: =IF(G8="","",IF(G8<Premissas!$C$8,"< 1,00",IF(G8<Premissas!$C$9,"1,00 – 1,19",IF(G8<Premissas!$C$10,"1,20 – 1,39",IF(G8<Premissas!$C$11,"1,40 – 1,59",IF(G8<Premissas!$C$12,"1,60 – 1,99","≥ 2,00")))))) -> 1,00 – 1,19 | L8: =IF(G8="","",MIN(Premissas!$C$17,IF(G8<Premissas!$C$8,Premissas!$E$7,IF(G8<Premissas!$C$9,Premissas!$E$8,IF(G8<Premissas!$C$10,Premissas!$E$9,IF(G8<Premissas!$C$11,Premissas!$E$10,IF(G8<Premissas!$C$12,Premissas!$E$11,Premissas!$E$12))))))) -> 100 | M8: =IF(OR(L8="",L8=0),0,L8/Premissas!$C$16) -> 3.8461538 | N8: =IF(L8>=Premissas!$C$17,"SIM","NÃO") -> NÃO
A9: 7 | B9: 46632 | C9: ARTHUR PEREIRA | D9: 1942 | E9: RECEBIMENTO | F9: =COUNTIFS(Detalhe_Registro!$A:$A,A9,Detalhe_Registro!$D:$D,B9) -> 1 | G9: 1.058824 | H9: 1.058824 | I9: =SUMIFS(Detalhe_Registro!$F:$F,Detalhe_Registro!$A:$A,A9,Detalhe_Registro!$D:$D,B9) -> 2235 | J9: =SUMIFS(Detalhe_Registro!$G:$G,Detalhe_Registro!$A:$A,A9,Detalhe_Registro!$D:$D,B9) -> 123.77 | K9: =IF(G9="","",IF(G9<Premissas!$C$8,"< 1,00",IF(G9<Premissas!$C$9,"1,00 – 1,19",IF(G9<Premissas!$C$10,"1,20 – 1,39",IF(G9<Premissas!$C$11,"1,40 – 1,59",IF(G9<Premissas!$C$12,"1,60 – 1,99","≥ 2,00")))))) -> 1,00 – 1,19 | L9: =IF(G9="","",MIN(Premissas!$C$17,IF(G9<Premissas!$C$8,Premissas!$E$7,IF(G9<Premissas!$C$9,Premissas!$E$8,IF(G9<Premissas!$C$10,Premissas!$E$9,IF(G9<Premissas!$C$11,Premissas!$E$10,IF(G9<Premissas!$C$12,Premissas!$E$11,Premissas!$E$12))))))) -> 100 | M9: =IF(OR(L9="",L9=0),0,L9/Premissas!$C$16) -> 3.8461538 | N9: =IF(L9>=Premissas!$C$17,"SIM","NÃO") -> NÃO
A10: 7 | B10: 5448530 | C10: Alef Paixao do Nascimento | D10: 1942 | E10: CARREGAMENTO | F10: =COUNTIFS(Detalhe_Registro!$A:$A,A10,Detalhe_Registro!$D:$D,B10) -> 1 | G10: 2.045455 | H10: 2.045455 | I10: =SUMIFS(Detalhe_Registro!$F:$F,Detalhe_Registro!$A:$A,A10,Detalhe_Registro!$D:$D,B10) -> 1299 | J10: =SUMIFS(Detalhe_Registro!$G:$G,Detalhe_Registro!$A:$A,A10,Detalhe_Registro!$D:$D,B10) -> 28.93 | K10: =IF(G10="","",IF(G10<Premissas!$C$8,"< 1,00",IF(G10<Premissas!$C$9,"1,00 – 1,19",IF(G10<Premissas!$C$10,"1,20 – 1,39",IF(G10<Premissas!$C$11,"1,40 – 1,59",IF(G10<Premissas!$C$12,"1,60 – 1,99","≥ 2,00")))))) -> ≥ 2,00 | L10: =IF(G10="","",MIN(Premissas!$C$17,IF(G10<Premissas!$C$8,Premissas!$E$7,IF(G10<Premissas!$C$9,Premissas!$E$8,IF(G10<Premissas!$C$10,Premissas!$E$9,IF(G10<Premissas!$C$11,Premissas!$E$10,IF(G10<Premissas!$C$12,Premissas!$E$11,Premissas!$E$12))))))) -> 750 | M10: =IF(OR(L10="",L10=0),0,L10/Premissas!$C$16) -> 28.846154 | N10: =IF(L10>=Premissas!$C$17,"SIM","NÃO") -> SIM
A11: 7 | B11: 690554 | C11: Andre Gomes Lima | D11: 1942 | E11: PUXADA RECEB | RECEBIMENTO | F11: =COUNTIFS(Detalhe_Registro!$A:$A,A11,Detalhe_Registro!$D:$D,B11) -> 2 | G11: 2.647059 | H11: 1.948529 | I11: =SUMIFS(Detalhe_Registro!$F:$F,Detalhe_Registro!$A:$A,A11,Detalhe_Registro!$D:$D,B11) -> 4744 | J11: =SUMIFS(Detalhe_Registro!$G:$G,Detalhe_Registro!$A:$A,A11,Detalhe_Registro!$D:$D,B11) -> 106.95 | K11: =IF(G11="","",IF(G11<Premissas!$C$8,"< 1,00",IF(G11<Premissas!$C$9,"1,00 – 1,19",IF(G11<Premissas!$C$10,"1,20 – 1,39",IF(G11<Premissas!$C$11,"1,40 – 1,59",IF(G11<Premissas!$C$12,"1,60 – 1,99","≥ 2,00")))))) -> ≥ 2,00 | L11: =IF(G11="","",MIN(Premissas!$C$17,IF(G11<Premissas!$C$8,Premissas!$E$7,IF(G11<Premissas!$C$9,Premissas!$E$8,IF(G11<Premissas!$C$10,Premissas!$E$9,IF(G11<Premissas!$C$11,Premissas!$E$10,IF(G11<Premissas!$C$12,Premissas!$E$11,Premissas!$E$12))))))) -> 750 | M11: =IF(OR(L11="",L11=0),0,L11/Premissas!$C$16) -> 28.846154 | N11: =IF(L11>=Premissas!$C$17,"SIM","NÃO") -> SIM
A12: 7 | B12: 5030994 | C12: Aron Ribeiro Pereira | D12: 1942 | E12: CARREGAMENTO | F12: =COUNTIFS(Detalhe_Registro!$A:$A,A12,Detalhe_Registro!$D:$D,B12) -> 1 | G12: 3.227273 | H12: 3.227273 | I12: =SUMIFS(Detalhe_Registro!$F:$F,Detalhe_Registro!$A:$A,A12,Detalhe_Registro!$D:$D,B12) -> 180 | J12: =SUMIFS(Detalhe_Registro!$G:$G,Detalhe_Registro!$A:$A,A12,Detalhe_Registro!$D:$D,B12) -> 2.52 | K12: =IF(G12="","",IF(G12<Premissas!$C$8,"< 1,00",IF(G12<Premissas!$C$9,"1,00 – 1,19",IF(G12<Premissas!$C$10,"1,20 – 1,39",IF(G12<Premissas!$C$11,"1,40 – 1,59",IF(G12<Premissas!$C$12,"1,60 – 1,99","≥ 2,00")))))) -> ≥ 2,00 | L12: =IF(G12="","",MIN(Premissas!$C$17,IF(G12<Premissas!$C$8,Premissas!$E$7,IF(G12<Premissas!$C$9,Premissas!$E$8,IF(G12<Premissas!$C$10,Premissas!$E$9,IF(G12<Premissas!$C$11,Premissas!$E$10,IF(G12<Premissas!$C$12,Premissas!$E$11,Premissas!$E$12))))))) -> 750 | M12: =IF(OR(L12="",L12=0),0,L12/Premissas!$C$16) -> 28.846154 | N12: =IF(L12>=Premissas!$C$17,"SIM","NÃO") -> SIM
A13: 7 | B13: 5854709 | C13: Arthur Filho Barbosa Ribeiro Junior | D13: 1942 | E13: PUXADA RECEB | F13: =COUNTIFS(Detalhe_Registro!$A:$A,A13,Detalhe_Registro!$D:$D,B13) -> 1 | G13: 1.25 | H13: 1.25 | I13: =SUMIFS(Detalhe_Registro!$F:$F,Detalhe_Registro!$A:$A,A13,Detalhe_Registro!$D:$D,B13) -> 2062 | J13: =SUMIFS(Detalhe_Registro!$G:$G,Detalhe_Registro!$A:$A,A13,Detalhe_Registro!$D:$D,B13) -> 102.15 | K13: =IF(G13="","",IF(G13<Premissas!$C$8,"< 1,00",IF(G13<Premissas!$C$9,"1,00 – 1,19",IF(G13<Premissas!$C$10,"1,20 – 1,39",IF(G13<Premissas!$C$11,"1,40 – 1,59",IF(G13<Premissas!$C$12,"1,60 – 1,99","≥ 2,00")))))) -> 1,20 – 1,39 | L13: =IF(G13="","",MIN(Premissas!$C$17,IF(G13<Premissas!$C$8,Premissas!$E$7,IF(G13<Premissas!$C$9,Premissas!$E$8,IF(G13<Premissas!$C$10,Premissas!$E$9,IF(G13<Premissas!$C$11,Premissas!$E$10,IF(G13<Premissas!$C$12,Premissas!$E$11,Premissas!$E$12))))))) -> 200 | M13: =IF(OR(L13="",L13=0),0,L13/Premissas!$C$16) -> 7.6923077 | N13: =IF(L13>=Premissas!$C$17,"SIM","NÃO") -> NÃO
... A1594: 8 | B1594: 5781639 | C1594: Yago Yuri Da Costa Silva | D1594: 930 | E1594: CARREGAMENTO | F1594: =COUNTIFS(Detalhe_Registro!$A:$A,A1594,Detalhe_Registro!$D:$D,B1594) -> 1 | G1594: 2.181818 | H1594: 2.181818 | I1594: =SUMIFS(Detalhe_Registro!$F:$F,Detalhe_Registro!$A:$A,A1594,Detalhe_Registro!$D:$D,B1594) -> 2001 | J1594: =SUMIFS(Detalhe_Registro!$G:$G,Detalhe_Registro!$A:$A,A1594,Detalhe_Registro!$D:$D,B1594) -> 41.8 | K1594: =IF(G1594="","",IF(G1594<Premissas!$C$8,"< 1,00",IF(G1594<Premissas!$C$9,"1,00 – 1,19",IF(G1594<Premissas!$C$10,"1,20 – 1,39",IF(G1594<Premissas!$C$11,"1,40 – 1,59",IF(G1594<Premissas!$C$12,"1,60 – 1,99","≥ 2,00")))))) -> ≥ 2,00 | L1594: =IF(G1594="","",MIN(Premissas!$C$17,IF(G1594<Premissas!$C$8,Premissas!$E$7,IF(G1594<Premissas!$C$9,Premissas!$E$8,IF(G1594<Premissas!$C$10,Premissas!$E$9,IF(G1594<Premissas!$C$11,Premissas!$E$10,IF(G1594<Premissas!$C$12,Premissas!$E$11,Premissas!$E$12))))))) -> 750 | M1594: =IF(OR(L1594="",L1594=0),0,L1594/Premissas!$C$16) -> 28.846154 | N1594: =IF(L1594>=Premissas!$C$17,"SIM","NÃO") -> SIM

Sheet Resumo_Mes_CD
A1: RESUMO POR MÊS E CD — CUSTO MENSAL, DIÁRIO E LINHA DE GANHO
A3: MES | B3: CD | C3: HCs REG. | D3: CUSTO_MENSAL | E3: HCs_ABAIXO | F3: HCs_TETO | G3: %_ABAIXO | H3: %_TETO | I3: GANHO_30% | J3: CENARIO_30% | K3: CUSTO_DIARIO
A4: 7 | B4: 409 | C4: =COUNTIFS(Consolidado_HC!$A:$A,A4,Consolidado_HC!$D:$D,B4) -> 147 | D4: =SUMIFS(Consolidado_HC!$L:$L,Consolidado_HC!$A:$A,A4,Consolidado_HC!$D:$D,B4) -> 56650 | E4: =COUNTIFS(Consolidado_HC!$A:$A,A4,Consolidado_HC!$D:$D,B4,Consolidado_HC!$L:$L,0) -> 29 | F4: =COUNTIFS(Consolidado_HC!$A:$A,A4,Consolidado_HC!$D:$D,B4,Consolidado_HC!$N:$N,"SIM") -> 50 | G4: =IF(C4=0,0,E4/C4) -> 0.19727891 | H4: =IF(C4=0,0,F4/C4) -> 0.34013605 | I4: =ROUND(E4*0.3*Premissas!E8,0) -> 870 | J4: =D4+I4 -> 57520 | K4: =IF(Premissas!$C$16=0,0,D4/Premissas!$C$16) -> 2178.8462
A5: 7 | B5: 930 | C5: =COUNTIFS(Consolidado_HC!$A:$A,A5,Consolidado_HC!$D:$D,B5) -> 177 | D5: =SUMIFS(Consolidado_HC!$L:$L,Consolidado_HC!$A:$A,A5,Consolidado_HC!$D:$D,B5) -> 58400 | E5: =COUNTIFS(Consolidado_HC!$A:$A,A5,Consolidado_HC!$D:$D,B5,Consolidado_HC!$L:$L,0) -> 67 | F5: =COUNTIFS(Consolidado_HC!$A:$A,A5,Consolidado_HC!$D:$D,B5,Consolidado_HC!$N:$N,"SIM") -> 53 | G5: =IF(C5=0,0,E5/C5) -> 0.37853107 | H5: =IF(C5=0,0,F5/C5) -> 0.29943503 | I5: =ROUND(E5*0.3*Premissas!E8,0) -> 2010 | J5: =D5+I5 -> 60410 | K5: =IF(Premissas!$C$16=0,0,D5/Premissas!$C$16) -> 2246.1538
A6: 7 | B6: 1942 | C6: =COUNTIFS(Consolidado_HC!$A:$A,A6,Consolidado_HC!$D:$D,B6) -> 74 | D6: =SUMIFS(Consolidado_HC!$L:$L,Consolidado_HC!$A:$A,A6,Consolidado_HC!$D:$D,B6) -> 25750 | E6: =COUNTIFS(Consolidado_HC!$A:$A,A6,Consolidado_HC!$D:$D,B6,Consolidado_HC!$L:$L,0) -> 19 | F6: =COUNTIFS(Consolidado_HC!$A:$A,A6,Consolidado_HC!$D:$D,B6,Consolidado_HC!$N:$N,"SIM") -> 24 | G6: =IF(C6=0,0,E6/C6) -> 0.25675676 | H6: =IF(C6=0,0,F6/C6) -> 0.32432432 | I6: =ROUND(E6*0.3*Premissas!E8,0) -> 570 | J6: =D6+I6 -> 26320 | K6: =IF(Premissas!$C$16=0,0,D6/Premissas!$C$16) -> 990.38462
A7: 7 | B7: 1953 | C7: =COUNTIFS(Consolidado_HC!$A:$A,A7,Consolidado_HC!$D:$D,B7) -> 51 | D7: =SUMIFS(Consolidado_HC!$L:$L,Consolidado_HC!$A:$A,A7,Consolidado_HC!$D:$D,B7) -> 30100 | E7: =COUNTIFS(Consolidado_HC!$A:$A,A7,Consolidado_HC!$D:$D,B7,Consolidado_HC!$L:$L,0) -> 5 | F7: =COUNTIFS(Consolidado_HC!$A:$A,A7,Consolidado_HC!$D:$D,B7,Consolidado_HC!$N:$N,"SIM") -> 34 | G7: =IF(C7=0,0,E7/C7) -> 0.098039216 | H7: =IF(C7=0,0,F7/C7) -> 0.66666667 | I7: =ROUND(E7*0.3*Premissas!E8,0) -> 150 | J7: =D7+I7 -> 30250 | K7: =IF(Premissas!$C$16=0,0,D7/Premissas!$C$16) -> 1157.6923
A8: 7 | B8: 1974 | C8: =COUNTIFS(Consolidado_HC!$A:$A,A8,Consolidado_HC!$D:$D,B8) -> 30 | D8: =SUMIFS(Consolidado_HC!$L:$L,Consolidado_HC!$A:$A,A8,Consolidado_HC!$D:$D,B8) -> 19050 | E8: =COUNTIFS(Consolidado_HC!$A:$A,A8,Consolidado_HC!$D:$D,B8,Consolidado_HC!$L:$L,0) -> 1 | F8: =COUNTIFS(Consolidado_HC!$A:$A,A8,Consolidado_HC!$D:$D,B8,Consolidado_HC!$N:$N,"SIM") -> 21 | G8: =IF(C8=0,0,E8/C8) -> 0.033333333 | H8: =IF(C8=0,0,F8/C8) -> 0.7 | I8: =ROUND(E8*0.3*Premissas!E8,0) -> 30 | J8: =D8+I8 -> 19080 | K8: =IF(Premissas!$C$16=0,0,D8/Premissas!$C$16) -> 732.69231
A9: 7 | B9: 1979 | C9: =COUNTIFS(Consolidado_HC!$A:$A,A9,Consolidado_HC!$D:$D,B9) -> 17 | D9: =SUMIFS(Consolidado_HC!$L:$L,Consolidado_HC!$A:$A,A9,Consolidado_HC!$D:$D,B9) -> 3900 | E9: =COUNTIFS(Consolidado_HC!$A:$A,A9,Consolidado_HC!$D:$D,B9,Consolidado_HC!$L:$L,0) -> 7 | F9: =COUNTIFS(Consolidado_HC!$A:$A,A9,Consolidado_HC!$D:$D,B9,Consolidado_HC!$N:$N,"SIM") -> 3 | G9: =IF(C9=0,0,E9/C9) -> 0.41176471 | H9: =IF(C9=0,0,F9/C9) -> 0.17647059 | I9: =ROUND(E9*0.3*Premissas!E8,0) -> 210 | J9: =D9+I9 -> 4110 | K9: =IF(Premissas!$C$16=0,0,D9/Premissas!$C$16) -> 150
A10: 7 | B10: 7801 | C10: =COUNTIFS(Consolidado_HC!$A:$A,A10,Consolidado_HC!$D:$D,B10) -> 292 | D10: =SUMIFS(Consolidado_HC!$L:$L,Consolidado_HC!$A:$A,A10,Consolidado_HC!$D:$D,B10) -> 20150 | E10: =COUNTIFS(Consolidado_HC!$A:$A,A10,Consolidado_HC!$D:$D,B10,Consolidado_HC!$L:$L,0) -> 217 | F10: =COUNTIFS(Consolidado_HC!$A:$A,A10,Consolidado_HC!$D:$D,B10,Consolidado_HC!$N:$N,"SIM") -> 7 | G10: =IF(C10=0,0,E10/C10) -> 0.74315068 | H10: =IF(C10=0,0,F10/C10) -> 0.023972603 | I10: =ROUND(E10*0.3*Premissas!E8,0) -> 6510 | J10: =D10+I10 -> 26660 | K10: =IF(Premissas!$C$16=0,0,D10/Premissas!$C$16) -> 775
A11: 8 | B11: 409 | C11: =COUNTIFS(Consolidado_HC!$A:$A,A11,Consolidado_HC!$D:$D,B11) -> 148 | D11: =SUMIFS(Consolidado_HC!$L:$L,Consolidado_HC!$A:$A,A11,Consolidado_HC!$D:$D,B11) -> 48450 | E11: =COUNTIFS(Consolidado_HC!$A:$A,A11,Consolidado_HC!$D:$D,B11,Consolidado_HC!$L:$L,0) -> 43 | F11: =COUNTIFS(Consolidado_HC!$A:$A,A11,Consolidado_HC!$D:$D,B11,Consolidado_HC!$N:$N,"SIM") -> 38 | G11: =IF(C11=0,0,E11/C11) -> 0.29054054 | H11: =IF(C11=0,0,F11/C11) -> 0.25675676 | I11: =ROUND(E11*0.3*Premissas!E8,0) -> 1290 | J11: =D11+I11 -> 49740 | K11: =IF(Premissas!$C$16=0,0,D11/Premissas!$C$16) -> 1863.4615
A12: 8 | B12: 930 | C12: =COUNTIFS(Consolidado_HC!$A:$A,A12,Consolidado_HC!$D:$D,B12) -> 170 | D12: =SUMIFS(Consolidado_HC!$L:$L,Consolidado_HC!$A:$A,A12,Consolidado_HC!$D:$D,B12) -> 51950 | E12: =COUNTIFS(Consolidado_HC!$A:$A,A12,Consolidado_HC!$D:$D,B12,Consolidado_HC!$L:$L,0) -> 68 | F12: =COUNTIFS(Consolidado_HC!$A:$A,A12,Consolidado_HC!$D:$D,B12,Consolidado_HC!$N:$N,"SIM") -> 50 | G12: =IF(C12=0,0,E12/C12) -> 0.4 | H12: =IF(C12=0,0,F12/C12) -> 0.29411765 | I12: =ROUND(E12*0.3*Premissas!E8,0) -> 2040 | J12: =D12+I12 -> 53990 | K12: =IF(Premissas!$C$16=0,0,D12/Premissas!$C$16) -> 1998.0769
A13: 8 | B13: 1942 | C13: =COUNTIFS(Consolidado_HC!$A:$A,A13,Consolidado_HC!$D:$D,B13) -> 78 | D13: =SUMIFS(Consolidado_HC!$L:$L,Consolidado_HC!$A:$A,A13,Consolidado_HC!$D:$D,B13) -> 22200 | E13: =COUNTIFS(Consolidado_HC!$A:$A,A13,Consolidado_HC!$D:$D,B13,Consolidado_HC!$L:$L,0) -> 24 | F13: =COUNTIFS(Consolidado_HC!$A:$A,A13,Consolidado_HC!$D:$D,B13,Consolidado_HC!$N:$N,"SIM") -> 19 | G13: =IF(C13=0,0,E13/C13) -> 0.30769231 | H13: =IF(C13=0,0,F13/C13) -> 0.24358974 | I13: =ROUND(E13*0.3*Premissas!E8,0) -> 720 | J13: =D13+I13 -> 22920 | K13: =IF(Premissas!$C$16=0,0,D13/Premissas!$C$16) -> 853.84615
A14: 8 | B14: 1953 | C14: =COUNTIFS(Consolidado_HC!$A:$A,A14,Consolidado_HC!$D:$D,B14) -> 50 | D14: =SUMIFS(Consolidado_HC!$L:$L,Consolidado_HC!$A:$A,A14,Consolidado_HC!$D:$D,B14) -> 26200 | E14: =COUNTIFS(Consolidado_HC!$A:$A,A14,Consolidado_HC!$D:$D,B14,Consolidado_HC!$L:$L,0) -> 10 | F14: =COUNTIFS(Consolidado_HC!$A:$A,A14,Consolidado_HC!$D:$D,B14,Consolidado_HC!$N:$N,"SIM") -> 30 | G14: =IF(C14=0,0,E14/C14) -> 0.2 | H14: =IF(C14=0,0,F14/C14) -> 0.6 | I14: =ROUND(E14*0.3*Premissas!E8,0) -> 300 | J14: =D14+I14 -> 26500 | K14: =IF(Premissas!$C$16=0,0,D14/Premissas!$C$16) -> 1007.6923
A15: 8 | B15: 1974 | C15: =COUNTIFS(Consolidado_HC!$A:$A,A15,Consolidado_HC!$D:$D,B15) -> 26 | D15: =SUMIFS(Consolidado_HC!$L:$L,Consolidado_HC!$A:$A,A15,Consolidado_HC!$D:$D,B15) -> 14500 | E15: =COUNTIFS(Consolidado_HC!$A:$A,A15,Consolidado_HC!$D:$D,B15,Consolidado_HC!$L:$L,0) -> 2 | F15: =COUNTIFS(Consolidado_HC!$A:$A,A15,Consolidado_HC!$D:$D,B15,Consolidado_HC!$N:$N,"SIM") -> 16 | G15: =IF(C15=0,0,E15/C15) -> 0.076923077 | H15: =IF(C15=0,0,F15/C15) -> 0.61538462 | I15: =ROUND(E15*0.3*Premissas!E8,0) -> 60 | J15: =D15+I15 -> 14560 | K15: =IF(Premissas!$C$16=0,0,D15/Premissas!$C$16) -> 557.69231
A16: 8 | B16: 1979 | C16: =COUNTIFS(Consolidado_HC!$A:$A,A16,Consolidado_HC!$D:$D,B16) -> 19 | D16: =SUMIFS(Consolidado_HC!$L:$L,Consolidado_HC!$A:$A,A16,Consolidado_HC!$D:$D,B16) -> 4550 | E16: =COUNTIFS(Consolidado_HC!$A:$A,A16,Consolidado_HC!$D:$D,B16,Consolidado_HC!$L:$L,0) -> 7 | F16: =COUNTIFS(Consolidado_HC!$A:$A,A16,Consolidado_HC!$D:$D,B16,Consolidado_HC!$N:$N,"SIM") -> 3 | G16: =IF(C16=0,0,E16/C16) -> 0.36842105 | H16: =IF(C16=0,0,F16/C16) -> 0.15789474 | I16: =ROUND(E16*0.3*Premissas!E8,0) -> 210 | J16: =D16+I16 -> 4760 | K16: =IF(Premissas!$C$16=0,0,D16/Premissas!$C$16) -> 175
A17: 8 | B17: 7801 | C17: =COUNTIFS(Consolidado_HC!$A:$A,A17,Consolidado_HC!$D:$D,B17) -> 45 | D17: =SUMIFS(Consolidado_HC!$L:$L,Consolidado_HC!$A:$A,A17,Consolidado_HC!$D:$D,B17) -> 4200 | E17: =COUNTIFS(Consolidado_HC!$A:$A,A17,Consolidado_HC!$D:$D,B17,Consolidado_HC!$L:$L,0) -> 33 | F17: =COUNTIFS(Consolidado_HC!$A:$A,A17,Consolidado_HC!$D:$D,B17,Consolidado_HC!$N:$N,"SIM") -> 1 | G17: =IF(C17=0,0,E17/C17) -> 0.73333333 | H17: =IF(C17=0,0,F17/C17) -> 0.022222222 | I17: =ROUND(E17*0.3*Premissas!E8,0) -> 990 | J17: =D17+I17 -> 5190 | K17: =IF(Premissas!$C$16=0,0,D17/Premissas!$C$16) -> 161.53846
A18: TOTAL | C18: =SUM(C4:C17) -> 1324 | D18: =SUM(D4:D17) -> 386050 | E18: =SUM(E4:E17) -> 532 | F18: =SUM(F4:F17) -> 349 | I18: =SUM(I4:I17) -> 15960 | J18: =SUM(J4:J17) -> 402010 | K18: =IF(Premissas!$C$16=0,0,D18/Premissas!$C$16) -> 14848.077

Sheet Comparativo_Jul_Ago
A1: COMPARATIVO JULHO × AGOSTO — POR CD
A3: CD | B3: HCs_JUL | C3: HCs_AGO | D3: Δ_HCs | E3: CUSTO_JUL | F3: CUSTO_AGO | G3: Δ_CUSTO | H3: %_ABAIXO_JUL | I3: %_ABAIXO_AGO | J3: Δ_pp_ABAIXO | K3: FATOR_MED_JUL | L3: FATOR_MED_AGO
A4: 1942 | B4: 74 | C4: 78 | D4: 4 | E4: 25250 | F4: 22200 | G4: -3050 | H4: 0.25675676 | I4: 0.30769231 | J4: 0.050935551 | K4: 1.87 | L4: 1.88
A5: 1953 | B5: 51 | C5: 50 | D5: -1 | E5: 29600 | F5: 26200 | G5: -3400 | H5: 0.098039216 | I5: 0.2 | J5: 0.10196078 | K5: 2.8 | L5: 3.36
A6: 1965 | B6: 0 | C6: 269 | D6: 269 | E6: 0 | F6: 31950 | G6: 31950 | H6: 0 | I6: 0.65427509 | J6: 0.65427509 | K6: 0 | L6: 1.01
A7: 1974 | B7: 30 | C7: 26 | D7: -4 | E7: 19050 | F7: 14250 | G7: -4800 | H7: 0.033333333 | I7: 0.076923077 | J7: 0.043589744 | K7: 2.73 | L7: 2.58
A8: 1979 | B8: 17 | C8: 19 | D8: 2 | E8: 3900 | F8: 4550 | G8: 650 | H8: 0.41176471 | I8: 0.36842105 | J8: -0.043343653 | K8: 2.52 | L8: 1.61
A9: 409 | B9: 147 | C9: 148 | D9: 1 | E9: 56400 | F9: 47450 | G9: -8950 | H9: 0.19727891 | I9: 0.29054054 | J9: 0.093261629 | K9: 1.94 | L9: 1.89
A10: 7801 | B10: 292 | C10: 45 | D10: -247 | E10: 20150 | F10: 4200 | G10: -15950 | H10: 0.74315068 | I10: 0.73333333 | J10: -0.0098173516 | K10: 0.81 | L10: 0.94
A11: 930 | B11: 177 | C11: 170 | D11: -7 | E11: 57650 | F11: 51700 | G11: -5950 | H11: 0.37853107 | I11: 0.4 | J11: 0.021468927 | K11: 1.86 | L11: 1.58
A12: TOTAL | B12: 788 | C12: 805 | D12: 17 | E12: 212000 | F12: 202500 | G12: -9500 | H12: 0.43781726 | I12: 0.45093168 | J12: 0.013114418 | K12: 1.59 | L12: 1.59
A14: Leitura: Δ_pp_ABAIXO negativo = melhora (menos gente abaixo da meta). Δ_CUSTO = variação do incentivo.

Sheet Projecao_Produtividade(const)
A1: PROJEÇÃO DE PRODUTIVIDADE E RETORNO DO INCENTIVO
A3: Simulação de redução
A4: % dos HCs abaixo da meta que sobem p/ 1ª faixa (1,00–1,19) | B4: 0.3
A5: Ganho médio de produtividade desses HCs (ex.: +15%) | B5: 0.15
A6: Custo médio mensal de 1 HC (salário+encargos) R$ | B6: 4940
A7: Elasticidade corte Separação: 1 pp a mais no ressuprimento → redução de X% no corte | B7: 0.05
A8: Custo médio mensal estimado de ruptura/corte (Separação) R$ | B8: 50000

Sheet Base_Nova
A1: CD | B1: Data | C1: ID | D1: Nome | E1: Quantidade | F1: Funções | G1: Cód. QTD Funções | H1: QTD Funções
A2: 930 | B2: 46280 | C2: T620222 | D2: JOSE RENIEL SILVA FARIAS | E2: 34 | F2: Carregamento | G2: 1 | H2: 1
A3: 930 | B3: 46280 | C3: T720420 | D3: Fabio DOS SANTOS SILVA | E3: 53 | F3: Empilhadeira | G3: 2 | H3: 1
A4: 930 | B4: 46280 | C4: 122853 | D4: ROSE KATIA DE OLIVEIRA | E4: 38 | F4: Recebimento | G4: 4 | H4: 1
A5: 930 | B5: 46280 | C5: 161429 | D5: JOAO GOMES DE ALMEIDA | E5: 8 | F5: Empilhadeira+Puxada | G5: 23 | H5: 2
A6: 930 | B6: 46280 | C6: 176631 | D6: LUCAS ANDRADE CAFE | E6: 13 | F6: Recebimento | G6: 4 | H6: 1
A7: 930 | B7: 46280 | C7: 28887 | D7: MARILZA DE MATOS GOMES | E7: 37 | F7: Recebimento | G7: 4 | H7: 1
A8: 930 | B8: 46280 | C8: 372952 | D8: MARCOS ROBERTO DE SOUZA | E8: 56 | F8: Empilhadeira+Puxada | G8: 23 | H8: 2
A9: 930 | B9: 46280 | C9: 383180 | D9: SEVERINO ANTONIO | E9: 56 | F9: Empilhadeira+Puxada | G9: 23 | H9: 2
A10: 930 | B10: 46280 | C10: 422175 | D10: MIKE HENRIQUE VINICIUS | E10: 8 | F10: Carregamento | G10: 1 | H10: 1
A11: 930 | B11: 46280 | C11: 435411 | D11: JOSE EVANGELISTA DA SILVA | E11: 79 | F11: Empilhadeira+Puxada | G11: 23 | H11: 2
A12: 930 | B12: 46280 | C12: 4394453 | D12: GEOVANE AQUINO DE LIMA | E12: 10 | F12: Carregamento | G12: 1 | H12: 1
A13: 930 | B13: 46280 | C13: 4531485 | D13: GUILHERME DE OLIVEIRA SILVA | E13: 35 | F13: Carregamento | G13: 1 | H13: 1
... A10302: 1953 | B10302: 46220 | C10302: 700842 | D10302: VITOR BERTO DIAS DA SILVA | E10302: 20 | F10302: Empilhadeira+Recebimento | G10302: 24 | H10302: 2
A10303: 1965 | B10303: 46280 | C10303: T40001283 | D10303: LUCAS PEREIRA ARAUJO | E10303: 21 | F10303: Carregamento | G10303: 1 | H10303: 1
