Workbook

Sheet Premissas
A1: MODELO DE INCENTIVO À PRODUTIVIDADE — SOMENTE GPA
A2: Escopo | B2: Somente registros da empresa GPA. A aba Base contém a base GPA usada no estudo.
A3: Período da base | B3: 7
A4: Dias úteis para rateio diário | B4: 26
A5: Regra | B5: Melhor fator do HC entre atividades elegíveis.
A6: Exclusão | B6: Atividades contendo SEPARAÇÃO.
A7: Meta em branco | B7: Meta da mesma atividade no CD 1942; sem referência, não recebe incentivo.
A8: Limite faixa 1 | B8: 1
A9: Limite faixa 2 | B9: 1.2
A10: Limite faixa 3 | B10: 1.4
A11: Limite faixa 4 | B11: 1.6
A12: Limite faixa 5 | B12: 2
A13: Valor faixa 0 | B13: 0
A14: Valor faixa 1 | B14: 100
A15: Valor faixa 2 | B15: 200
A16: Valor faixa 3 | B16: 350
A17: Valor faixa 4 | B17: 500
A18: Valor faixa 5 | B18: 750
A19: Observação diária | B19: O incentivo diário é um rateio do valor mensal. A base não possui data/dia de produção.
A20: Quantidade registros GPA | B20: 4427
A21: Quantidade CDs GPA | B21: 8
A22: CDs incluídos | B22: 409, 930, 1942, 1953, 1965, 1974, 1979, 7801

Sheet Base
A1: MES | B1: CD | C1: ATIVIDADE | D1: USUÁRIO | E1: COLABORADOR | F1: QUANTIDADE | G1: HORAS | H1: PRODUTIVIDADE | I1: META | J1: EMPRESA
A2: 7 | B2: 409 | C2: ATIVIDADE OP. EMP. | D2: 182403 | E2: Reginaldo Alves Araujo | F2: 2377 | G2: 66.81 | H2: 36 | I2: 25 | J2: GPA
A3: 7 | B3: 409 | C3: RECEBIMENTO | D3: 250187 | E3: Marcio Da Silva Rodrigues | F3: 1518 | G3: 30.47 | H3: 50 | I3: 25 | J3: GPA
A4: 7 | B4: 409 | C4: CARREGAMENTO | D4: 250896 | E4: Hugo Clementino Nunes | F4: 272 | G4: 4.08 | H4: 67 | I4: 24 | J4: GPA
A5: 7 | B5: 409 | C5: PUXADA RECEB | D5: 250896 | E5: Hugo Clementino Nunes | F5: 318 | G5: 9.38 | H5: 34 | I5: 22 | J5: GPA
A6: 7 | B6: 409 | C6: RECEBIMENTO | D6: 250896 | E6: Hugo Clementino Nunes | F6: 187 | G6: 7.68 | H6: 24 | I6: 25 | J6: GPA
A7: 7 | B7: 409 | C7: SEPARACAO | D7: 250896 | E7: Hugo Clementino Nunes | F7: 499 | G7: 6.21 | H7: 80 | I7: 105 | J7: GPA
A8: 7 | B8: 409 | C8: PUXADA RECEB | D8: 251239 | E8: Mauricio Rodrigues | F8: 124 | G8: 7.08 | H8: 18 | I8: 22 | J8: GPA
A9: 7 | B9: 409 | C9: PUXADA RECEB | D9: 251240 | E9: Gildo Antonio Barbosa | F9: 38 | G9: 1.3 | H9: 29 | I9: 22 | J9: GPA
A10: 7 | B10: 409 | C10: RECEBIMENTO | D10: 251240 | E10: Gildo Antonio Barbosa | F10: 3278 | G10: 39.72 | H10: 83 | I10: 25 | J10: GPA
A11: 7 | B11: 409 | C11: CARREGAMENTO | D11: 255199 | E11: Gilberton Santana De Moura | F11: 344 | G11: 7.68 | H11: 45 | I11: 24 | J11: GPA
A12: 7 | B12: 409 | C12: ATIVIDADE OP. EMP. | D12: 264318 | E12: Flavio Soares Da Silva | F12: 2828 | G12: 66.5 | H12: 43 | I12: 25 | J12: GPA
A13: 7 | B13: 409 | C13: SEPARACAO | D13: 264318 | E13: Flavio Soares Da Silva | F13: 714 | G13: 3.65 | H13: 196 | I13: 105 | J13: GPA
... A2091: 8 | B2091: 1942 | C2091: ATIVIDADE OP. EMP. | D2091: 85456 | E2091: GENIVALDO MANOEL | F2091: 1186 | G2091: 93.17 | H2091: 13 | I2091: 20 | J2091: GPA
A2092: 8 | B2092: 409 | C2092: ATIVIDADE OP. EMP. | D2092: 182403 | E2092: Reginaldo Alves Araujo | F2092: 2378 | G2092: 63.7 | H2092: 37 | I2092: 25 | J2092: GPA
A2093: 8 | B2093: 409 | C2093: RECEBIMENTO | D2093: 182403 | E2093: Reginaldo Alves Araujo | F2093: 1 | G2093: 0.17 | H2093: 6 | I2093: 25 | J2093: GPA
A2094: 8 | B2094: 409 | C2094: ATIVIDADE OP. EMP. | D2094: 245370 | E2094: Carlos Alberto Da Luz Teixeira | F2094: 1847 | G2094: 61.46 | H2094: 30 | I2094: 25 | J2094: GPA
A2095: 8 | B2095: 409 | C2095: CARREGAMENTO | D2095: 250187 | E2095: Marcio Da Silva Rodrigues | F2095: 31 | G2095: 0.38 | H2095: 82 | I2095: 24 | J2095: GPA
A2096: 8 | B2096: 409 | C2096: RECEBIMENTO | D2096: 250187 | E2096: Marcio Da Silva Rodrigues | F2096: 1249 | G2096: 29.61 | H2096: 42 | I2096: 25 | J2096: GPA
A2097: 8 | B2097: 409 | C2097: PUXADA RECEB | D2097: 250896 | E2097: Hugo Clementino Nunes | F2097: 5 | G2097: 1.42 | H2097: 4 | I2097: 22 | J2097: GPA
A2098: 8 | B2098: 409 | C2098: PUXADA RECEB | D2098: 251239 | E2098: Mauricio Rodrigues | F2098: 31 | G2098: 13.25 | H2098: 2 | I2098: 22 | J2098: GPA
A2099: 8 | B2099: 409 | C2099: RECEBIMENTO | D2099: 251239 | E2099: Mauricio Rodrigues | F2099: 1 | G2099: 1.15 | H2099: 1 | I2099: 25 | J2099: GPA
A2100: 8 | B2100: 409 | C2100: PUXADA RECEB | D2100: 251240 | E2100: Gildo Antonio Barbosa | F2100: 56 | G2100: 1.9 | H2100: 29 | I2100: 22 | J2100: GPA
A2101: 8 | B2101: 409 | C2101: RECEBIMENTO | D2101: 251240 | E2101: Gildo Antonio Barbosa | F2101: 2743 | G2101: 36.99 | H2101: 74 | I2101: 25 | J2101: GPA
A2102: 8 | B2102: 409 | C2102: CARREGAMENTO | D2102: 255199 | E2102: Gilberton Santana De Moura | F2102: 161 | G2102: 4.13 | H2102: 39 | I2102: 24 | J2102: GPA
A2103: 8 | B2103: 409 | C2103: ATIVIDADE OP. EMP. | D2103: 264318 | E2103: Flavio Soares Da Silva | F2103: 1467 | G2103: 34.83 | H2103: 42 | I2103: 25 | J2103: GPA
... A2945: 8 | B2945: 1965 | C2945: CARREGAMENTO | D2945: 2958732 | E2945: Gilvana Oliveira De Araujo | F2945: 192 | G2945: 9.96 | H2945: 19 | I2945: 0 | J2945: GPA
A2946: 8 | B2946: 1965 | C2946: SEPARACAO | D2946: 2991799 | E2946: Gustavo De Mello Dos Santos | F2946: 297 | G2946: 8.07 | H2946: 37 | J2946: GPA
A2947: 8 | B2947: 1965 | C2947: RECEBIMENTO | D2947: 30307 | E2947: MARIA VANDA DOS ANJOS CRUZ | F2947: 153 | G2947: 20.01 | H2947: 8 | I2947: 0 | J2947: GPA
A2948: 8 | B2948: 1965 | C2948: ATIVIDADE OP. EMP. | D2948: 308129 | E2948: Silvio Rodrigues Da Macena | F2948: 57 | G2948: 9.52 | H2948: 6 | I2948: 0 | J2948: GPA
A2949: 8 | B2949: 1965 | C2949: RECEBIMENTO | D2949: 308129 | E2949: Silvio Rodrigues Da Macena | F2949: 1 | G2949: 0.46 | H2949: 2 | I2949: 0 | J2949: GPA
A2950: 8 | B2950: 1965 | C2950: ATIVIDADE OP. EMP. | D2950: 308965 | E2950: ANDRE FERREIRA APOLINARIO | F2950: 961 | G2950: 104.26 | H2950: 9 | I2950: 0 | J2950: GPA
A2951: 8 | B2951: 1965 | C2951: RECEBIMENTO | D2951: 3155196 | E2951: CLAUDIO ROBERTO OTAVIO | F2951: 785 | G2951: 89.69 | H2951: 9 | I2951: 0 | J2951: GPA
A2952: 8 | B2952: 1965 | C2952: ATIVIDADE OP. EMP. | D2952: 316516 | E2952: EDMAR AGUIAR VIANA | F2952: 1909 | G2952: 177.75 | H2952: 11 | I2952: 0 | J2952: GPA
A2953: 8 | B2953: 1965 | C2953: ATIVIDADE OP. EMP. | D2953: 322452 | E2953: Givaldo Moreira Silva | F2953: 2709 | G2953: 159.88 | H2953: 17 | I2953: 0 | J2953: GPA
A2954: 8 | B2954: 1965 | C2954: CARREGAMENTO | D2954: 322452 | E2954: Givaldo Moreira Silva | F2954: 63 | G2954: 4.38 | H2954: 14 | I2954: 0 | J2954: GPA
A2955: 8 | B2955: 1965 | C2955: ATIVIDADE OP. EMP. | D2955: 324132 | E2955: ARIEL SOUZA OLIVEIRA | F2955: 1430 | G2955: 160.38 | H2955: 9 | I2955: 0 | J2955: GPA
A2956: 8 | B2956: 1965 | C2956: RECEBIMENTO | D2956: 3353583 | E2956: GILBERTO NOVAES DOS SANTOS | F2956: 1095 | G2956: 113.3 | H2956: 10 | I2956: 0 | J2956: GPA
A2957: 8 | B2957: 1965 | C2957: SEPARACAO | D2957: 3353583 | E2957: GILBERTO NOVAES DOS SANTOS | F2957: 61 | G2957: 0.84 | H2957: 73 | J2957: GPA
A2958: 8 | B2958: 1965 | C2958: CARREGAMENTO | D2958: 335416 | E2958: Dourivaldo Dias De Oliveira | F2958: 103 | G2958: 32.15 | H2958: 3 | I2958: 0 | J2958: GPA
...

Sheet Base_Origem_Completa
A1: MES | B1: CD | C1: ATIVIDADE | D1: USUÁRIO | E1: COLABORADOR | F1: QUANTIDADE | G1: HORAS | H1: PRODUTIVIDADE | I1: META | J1: EMPRESA
A2: 7 | B2: 409 | C2: ATIVIDADE OP. EMP. | D2: 182403 | E2: Reginaldo Alves Araujo | F2: 2377 | G2: 66.81 | H2: 36 | I2: 25 | J2: GPA
A3: 7 | B3: 409 | C3: RECEBIMENTO | D3: 250187 | E3: Marcio Da Silva Rodrigues | F3: 1518 | G3: 30.47 | H3: 50 | I3: 25 | J3: GPA
A4: 7 | B4: 409 | C4: CARREGAMENTO | D4: 250896 | E4: Hugo Clementino Nunes | F4: 272 | G4: 4.08 | H4: 67 | I4: 24 | J4: GPA
A5: 7 | B5: 409 | C5: PUXADA RECEB | D5: 250896 | E5: Hugo Clementino Nunes | F5: 318 | G5: 9.38 | H5: 34 | I5: 22 | J5: GPA
A6: 7 | B6: 409 | C6: RECEBIMENTO | D6: 250896 | E6: Hugo Clementino Nunes | F6: 187 | G6: 7.68 | H6: 24 | I6: 25 | J6: GPA
A7: 7 | B7: 409 | C7: SEPARACAO | D7: 250896 | E7: Hugo Clementino Nunes | F7: 499 | G7: 6.21 | H7: 80 | I7: 105 | J7: GPA
A8: 7 | B8: 409 | C8: PUXADA RECEB | D8: 251239 | E8: Mauricio Rodrigues | F8: 124 | G8: 7.08 | H8: 18 | I8: 22 | J8: GPA
A9: 7 | B9: 409 | C9: PUXADA RECEB | D9: 251240 | E9: Gildo Antonio Barbosa | F9: 38 | G9: 1.3 | H9: 29 | I9: 22 | J9: GPA
A10: 7 | B10: 409 | C10: RECEBIMENTO | D10: 251240 | E10: Gildo Antonio Barbosa | F10: 3278 | G10: 39.72 | H10: 83 | I10: 25 | J10: GPA
A11: 7 | B11: 409 | C11: CARREGAMENTO | D11: 255199 | E11: Gilberton Santana De Moura | F11: 344 | G11: 7.68 | H11: 45 | I11: 24 | J11: GPA
A12: 7 | B12: 409 | C12: ATIVIDADE OP. EMP. | D12: 264318 | E12: Flavio Soares Da Silva | F12: 2828 | G12: 66.5 | H12: 43 | I12: 25 | J12: GPA
A13: 7 | B13: 409 | C13: SEPARACAO | D13: 264318 | E13: Flavio Soares Da Silva | F13: 714 | G13: 3.65 | H13: 196 | I13: 105 | J13: GPA
... A581: 7 | B581: 1942 | C581: SEPARACAO | D581: 85456 | E581: GENIVALDO MANOEL | F581: 1010 | G581: 12.8 | H581: 79 | I581: 80 | J581: GPA
A582: 7 | B582: 1942 | C582: SEPARACAO | D582: T10184 | E582: BRUNO SANTOS DA SILVA | F582: 9903 | G582: 136.12 | H582: 73 | I582: 80 | J582: TERCEIRO
A583: 7 | B583: 1942 | C583: SEPARACAO | D583: T10185 | E583: RICARDO JOSE DA SILVA | F583: 4508 | G583: 63.02 | H583: 72 | I583: 80 | J583: TERCEIRO
A584: 7 | B584: 1942 | C584: SEPARACAO | D584: T10217 | E584: Gildevam Campo | F584: 1191 | G584: 8.72 | H584: 137 | I584: 80 | J584: TERCEIRO
A585: 7 | B585: 1942 | C585: SEPARACAO | D585: T10274 | E585: JHONY ELBERT SILVA DOS SANTOS | F585: 9796 | G585: 114.36 | H585: 86 | I585: 80 | J585: TERCEIRO
A586: 7 | B586: 1942 | C586: SEPARACAO | D586: T10292 | E586: MARCOS VINICIUS FELIX VALIM | F586: 5655 | G586: 82.95 | H586: 68 | I586: 80 | J586: TERCEIRO
A587: 7 | B587: 1942 | C587: SEPARACAO | D587: T10312 | E587: Marcio da Cunha | F587: 5206 | G587: 38.92 | H587: 134 | I587: 80 | J587: TERCEIRO
A588: 7 | B588: 1942 | C588: SEPARACAO | D588: T10324 | E588: GLEISON DE SOUSA SILVA | F588: 12774 | G588: 172.48 | H588: 74 | I588: 80 | J588: TERCEIRO
A589: 7 | B589: 1942 | C589: SEPARACAO | D589: T10329 | E589: ERIK OLIVEIRA DE MORAIS | F589: 1620 | G589: 22.05 | H589: 73 | I589: 80 | J589: TERCEIRO
A590: 7 | B590: 1942 | C590: SEPARACAO | D590: T10333 | E590: CARLOS DANIEL MATOS SILVA | F590: 7210 | G590: 84.06 | H590: 86 | I590: 80 | J590: TERCEIRO
A591: 7 | B591: 1942 | C591: SEPARACAO | D591: T10353 | E591: ISRAEL MANUEL DA SILVA | F591: 17465 | G591: 111.5 | H591: 157 | I591: 80 | J591: TERCEIRO
A592: 7 | B592: 1942 | C592: SEPARACAO | D592: T10371 | E592: GABRIEL AMORIM JESUS DA SILVA | F592: 9318 | G592: 80.38 | H592: 116 | I592: 80 | J592: TERCEIRO
A593: 7 | B593: 1942 | C593: SEPARACAO | D593: T10377 | E593: Vinicius Silva Cabra | F593: 14734 | G593: 107.03 | H593: 138 | I593: 80 | J593: TERCEIRO
... A624: 7 | B624: 1942 | C624: SEPARACAO | D624: T10638 | E624: Jorge Washington Maia | F624: 672 | G624: 19.11 | H624: 35 | I624: 80 | J624: TERCEIRO
A625: 7 | B625: 1953 | C625: SEPARACAO | D625: 195365 | E625: LUCAS DOS SANTOS COSME | F625: 20862 | G625: 124.43 | H625: 168 | I625: 110 | J625: GPA
A626: 7 | B626: 1953 | C626: SEPARACAO | D626: 2019122 | E626: Wyllamar Silva | F626: 24737 | G626: 161.49 | H626: 153 | I626: 110 | J626: GPA
A627: 7 | B627: 1953 | C627: SEPARACAO | D627: 202125 | E627: RODRIGO SILVA | F627: 297 | G627: 1.18 | H627: 252 | I627: 110 | J627: GPA
A628: 7 | B628: 1953 | C628: SEPARACAO | D628: 202219 | E628: Rudson Pablo Santos da Silva | F628: 1097 | G628: 5.93 | H628: 185 | I628: 110 | J628: GPA
A629: 7 | B629: 1953 | C629: PUXADA RECEB | D629: 202301 | E629: CARLOS CLEYTON TEIXEIRA | F629: 3 | G629: 6.78 | H629: 0 | I629: 15 | J629: GPA
A630: 7 | B630: 1953 | C630: SEPARACAO | D630: 202301 | E630: CARLOS CLEYTON TEIXEIRA | F630: 1508 | G630: 12.3 | H630: 123 | I630: 110 | J630: GPA
A631: 7 | B631: 1953 | C631: ATIVIDADE OP. EMP. | D631: 202320 | E631: ALEX MATOS FERREIRA | F631: 2 | G631: 0.11 | H631: 18 | I631: 19 | J631: GPA
A632: 7 | B632: 1953 | C632: SEPARACAO | D632: 202320 | E632: ALEX MATOS FERREIRA | F632: 959 | G632: 10.22 | H632: 94 | I632: 110 | J632: GPA
A633: 7 | B633: 1953 | C633: CARREGAMENTO | D633: 2504499 | E633: WEBHERGTE JOSE DE SOUZA | F633: 520 | G633: 12.28 | H633: 42 | I633: 18 | J633: GPA
A634: 7 | B634: 1953 | C634: PUXADA RECEB | D634: 2504499 | E634: WEBHERGTE JOSE DE SOUZA | F634: 29 | G634: 7.4 | H634: 4 | I634: 15 | J634: GPA
A635: 7 | B635: 1953 | C635: RECEBIMENTO | D635: 2504499 | E635: WEBHERGTE JOSE DE SOUZA | F635: 122 | G635: 4.76 | H635: 26 | I635: 19 | J635: GPA
A636: 7 | B636: 1953 | C636: SEPARACAO | D636: 2504499 | E636: WEBHERGTE JOSE DE SOUZA | F636: 26 | G636: 0.06 | H636: 433 | I636: 110 | J636: GPA
... A766: 7 | B766: 1953 | C766: SEPARACAO | D766: 700842 | E766: VITOR BERTO DIAS DA SILVA | F766: 19 | G766: 0.19 | H766: 100 | I766: 110 | J766: GPA
...

Sheet Detalhe_Registro
A1: MES | B1: CD | C1: ATIVIDADE | D1: USUÁRIO | E1: COLABORADOR | F1: QUANTIDADE | G1: HORAS | H1: PRODUTIVIDADE | I1: META | J1: EMPRESA | K1: META_USADA | L1: META_PREENCHIDA | M1: ELEGIVEL | N1: FATOR | O1: FAIXA | P1: VALOR_MENSAL_REG | Q1: VALOR_DIARIO_REG
A2: 7 | B2: 409 | C2: ATIVIDADE OP. EMP. | D2: 182403 | E2: Reginaldo Alves Araujo | F2: 2377 | G2: 66.81 | H2: 36 | I2: 25 | J2: GPA | K2: =IF(I2<>"",I2,IFERROR(INDEX(Base!$I:$I,MATCH(1,(Base!$C:$C=C2)*(Base!$I:$I<>""),0)),0)) | L2: =IF(AND(I2="",K2>0),"SIM","NÃO") | M2: =IF(ISNUMBER(SEARCH("SEPARA",UPPER(C2))),"NÃO","SIM") | N2: =IFERROR(H2/K2,0) | O2: =IF(M2="NÃO","EXCLUÍDO",IF(N2<Premissas!$B$8,"< 1,00",IF(N2<Premissas!$B$9,"1,00 – 1,19",IF(N2<Premissas!$B$10,"1,20 – 1,39",IF(N2<Premissas!$B$11,"1,40 – 1,59",IF(N2<Premissas!$B$12,"1,60 – 1,99","≥ 2,00")))))) | P2: =IF(OR(M2="NÃO",N2<Premissas!$B$8),Premissas!$B$13,IF(N2<Premissas!$B$9,Premissas!$B$14,IF(N2<Premissas!$B$10,Premissas!$B$15,IF(N2<Premissas!$B$11,Premissas!$B$16,IF(N2<Premissas!$B$12,Premissas!$B$17,Premissas!$B$18))))) | Q2: =IFERROR(P2/Premissas!$B$4,0)
A3: 7 | B3: 409 | C3: RECEBIMENTO | D3: 250187 | E3: Marcio Da Silva Rodrigues | F3: 1518 | G3: 30.47 | H3: 50 | I3: 25 | J3: GPA | K3: =IF(I3<>"",I3,IFERROR(INDEX(Base!$I:$I,MATCH(1,(Base!$C:$C=C3)*(Base!$I:$I<>""),0)),0)) | L3: =IF(AND(I3="",K3>0),"SIM","NÃO") | M3: =IF(ISNUMBER(SEARCH("SEPARA",UPPER(C3))),"NÃO","SIM") | N3: =IFERROR(H3/K3,0) | O3: =IF(M3="NÃO","EXCLUÍDO",IF(N3<Premissas!$B$8,"< 1,00",IF(N3<Premissas!$B$9,"1,00 – 1,19",IF(N3<Premissas!$B$10,"1,20 – 1,39",IF(N3<Premissas!$B$11,"1,40 – 1,59",IF(N3<Premissas!$B$12,"1,60 – 1,99","≥ 2,00")))))) | P3: =IF(OR(M3="NÃO",N3<Premissas!$B$8),Premissas!$B$13,IF(N3<Premissas!$B$9,Premissas!$B$14,IF(N3<Premissas!$B$10,Premissas!$B$15,IF(N3<Premissas!$B$11,Premissas!$B$16,IF(N3<Premissas!$B$12,Premissas!$B$17,Premissas!$B$18))))) | Q3: =IFERROR(P3/Premissas!$B$4,0)
A4: 7 | B4: 409 | C4: CARREGAMENTO | D4: 250896 | E4: Hugo Clementino Nunes | F4: 272 | G4: 4.08 | H4: 67 | I4: 24 | J4: GPA | K4: =IF(I4<>"",I4,IFERROR(INDEX(Base!$I:$I,MATCH(1,(Base!$C:$C=C4)*(Base!$I:$I<>""),0)),0)) | L4: =IF(AND(I4="",K4>0),"SIM","NÃO") | M4: =IF(ISNUMBER(SEARCH("SEPARA",UPPER(C4))),"NÃO","SIM") | N4: =IFERROR(H4/K4,0) | O4: =IF(M4="NÃO","EXCLUÍDO",IF(N4<Premissas!$B$8,"< 1,00",IF(N4<Premissas!$B$9,"1,00 – 1,19",IF(N4<Premissas!$B$10,"1,20 – 1,39",IF(N4<Premissas!$B$11,"1,40 – 1,59",IF(N4<Premissas!$B$12,"1,60 – 1,99","≥ 2,00")))))) | P4: =IF(OR(M4="NÃO",N4<Premissas!$B$8),Premissas!$B$13,IF(N4<Premissas!$B$9,Premissas!$B$14,IF(N4<Premissas!$B$10,Premissas!$B$15,IF(N4<Premissas!$B$11,Premissas!$B$16,IF(N4<Premissas!$B$12,Premissas!$B$17,Premissas!$B$18))))) | Q4: =IFERROR(P4/Premissas!$B$4,0)
A5: 7 | B5: 409 | C5: PUXADA RECEB | D5: 250896 | E5: Hugo Clementino Nunes | F5: 318 | G5: 9.38 | H5: 34 | I5: 22 | J5: GPA | K5: =IF(I5<>"",I5,IFERROR(INDEX(Base!$I:$I,MATCH(1,(Base!$C:$C=C5)*(Base!$I:$I<>""),0)),0)) | L5: =IF(AND(I5="",K5>0),"SIM","NÃO") | M5: =IF(ISNUMBER(SEARCH("SEPARA",UPPER(C5))),"NÃO","SIM") | N5: =IFERROR(H5/K5,0) | O5: =IF(M5="NÃO","EXCLUÍDO",IF(N5<Premissas!$B$8,"< 1,00",IF(N5<Premissas!$B$9,"1,00 – 1,19",IF(N5<Premissas!$B$10,"1,20 – 1,39",IF(N5<Premissas!$B$11,"1,40 – 1,59",IF(N5<Premissas!$B$12,"1,60 – 1,99","≥ 2,00")))))) | P5: =IF(OR(M5="NÃO",N5<Premissas!$B$8),Premissas!$B$13,IF(N5<Premissas!$B$9,Premissas!$B$14,IF(N5<Premissas!$B$10,Premissas!$B$15,IF(N5<Premissas!$B$11,Premissas!$B$16,IF(N5<Premissas!$B$12,Premissas!$B$17,Premissas!$B$18))))) | Q5: =IFERROR(P5/Premissas!$B$4,0)
A6: 7 | B6: 409 | C6: RECEBIMENTO | D6: 250896 | E6: Hugo Clementino Nunes | F6: 187 | G6: 7.68 | H6: 24 | I6: 25 | J6: GPA | K6: =IF(I6<>"",I6,IFERROR(INDEX(Base!$I:$I,MATCH(1,(Base!$C:$C=C6)*(Base!$I:$I<>""),0)),0)) | L6: =IF(AND(I6="",K6>0),"SIM","NÃO") | M6: =IF(ISNUMBER(SEARCH("SEPARA",UPPER(C6))),"NÃO","SIM") | N6: =IFERROR(H6/K6,0) | O6: =IF(M6="NÃO","EXCLUÍDO",IF(N6<Premissas!$B$8,"< 1,00",IF(N6<Premissas!$B$9,"1,00 – 1,19",IF(N6<Premissas!$B$10,"1,20 – 1,39",IF(N6<Premissas!$B$11,"1,40 – 1,59",IF(N6<Premissas!$B$12,"1,60 – 1,99","≥ 2,00")))))) | P6: =IF(OR(M6="NÃO",N6<Premissas!$B$8),Premissas!$B$13,IF(N6<Premissas!$B$9,Premissas!$B$14,IF(N6<Premissas!$B$10,Premissas!$B$15,IF(N6<Premissas!$B$11,Premissas!$B$16,IF(N6<Premissas!$B$12,Premissas!$B$17,Premissas!$B$18))))) | Q6: =IFERROR(P6/Premissas!$B$4,0)
A7: 7 | B7: 409 | C7: SEPARACAO | D7: 250896 | E7: Hugo Clementino Nunes | F7: 499 | G7: 6.21 | H7: 80 | I7: 105 | J7: GPA | K7: =IF(I7<>"",I7,IFERROR(INDEX(Base!$I:$I,MATCH(1,(Base!$C:$C=C7)*(Base!$I:$I<>""),0)),0)) | L7: =IF(AND(I7="",K7>0),"SIM","NÃO") | M7: =IF(ISNUMBER(SEARCH("SEPARA",UPPER(C7))),"NÃO","SIM") | N7: =IFERROR(H7/K7,0) | O7: =IF(M7="NÃO","EXCLUÍDO",IF(N7<Premissas!$B$8,"< 1,00",IF(N7<Premissas!$B$9,"1,00 – 1,19",IF(N7<Premissas!$B$10,"1,20 – 1,39",IF(N7<Premissas!$B$11,"1,40 – 1,59",IF(N7<Premissas!$B$12,"1,60 – 1,99","≥ 2,00")))))) | P7: =IF(OR(M7="NÃO",N7<Premissas!$B$8),Premissas!$B$13,IF(N7<Premissas!$B$9,Premissas!$B$14,IF(N7<Premissas!$B$10,Premissas!$B$15,IF(N7<Premissas!$B$11,Premissas!$B$16,IF(N7<Premissas!$B$12,Premissas!$B$17,Premissas!$B$18))))) | Q7: =IFERROR(P7/Premissas!$B$4,0)
A8: 7 | B8: 409 | C8: PUXADA RECEB | D8: 251239 | E8: Mauricio Rodrigues | F8: 124 | G8: 7.08 | H8: 18 | I8: 22 | J8: GPA | K8: =IF(I8<>"",I8,IFERROR(INDEX(Base!$I:$I,MATCH(1,(Base!$C:$C=C8)*(Base!$I:$I<>""),0)),0)) | L8: =IF(AND(I8="",K8>0),"SIM","NÃO") | M8: =IF(ISNUMBER(SEARCH("SEPARA",UPPER(C8))),"NÃO","SIM") | N8: =IFERROR(H8/K8,0) | O8: =IF(M8="NÃO","EXCLUÍDO",IF(N8<Premissas!$B$8,"< 1,00",IF(N8<Premissas!$B$9,"1,00 – 1,19",IF(N8<Premissas!$B$10,"1,20 – 1,39",IF(N8<Premissas!$B$11,"1,40 – 1,59",IF(N8<Premissas!$B$12,"1,60 – 1,99","≥ 2,00")))))) | P8: =IF(OR(M8="NÃO",N8<Premissas!$B$8),Premissas!$B$13,IF(N8<Premissas!$B$9,Premissas!$B$14,IF(N8<Premissas!$B$10,Premissas!$B$15,IF(N8<Premissas!$B$11,Premissas!$B$16,IF(N8<Premissas!$B$12,Premissas!$B$17,Premissas!$B$18))))) | Q8: =IFERROR(P8/Premissas!$B$4,0)
A9: 7 | B9: 409 | C9: PUXADA RECEB | D9: 251240 | E9: Gildo Antonio Barbosa | F9: 38 | G9: 1.3 | H9: 29 | I9: 22 | J9: GPA | K9: =IF(I9<>"",I9,IFERROR(INDEX(Base!$I:$I,MATCH(1,(Base!$C:$C=C9)*(Base!$I:$I<>""),0)),0)) | L9: =IF(AND(I9="",K9>0),"SIM","NÃO") | M9: =IF(ISNUMBER(SEARCH("SEPARA",UPPER(C9))),"NÃO","SIM") | N9: =IFERROR(H9/K9,0) | O9: =IF(M9="NÃO","EXCLUÍDO",IF(N9<Premissas!$B$8,"< 1,00",IF(N9<Premissas!$B$9,"1,00 – 1,19",IF(N9<Premissas!$B$10,"1,20 – 1,39",IF(N9<Premissas!$B$11,"1,40 – 1,59",IF(N9<Premissas!$B$12,"1,60 – 1,99","≥ 2,00")))))) | P9: =IF(OR(M9="NÃO",N9<Premissas!$B$8),Premissas!$B$13,IF(N9<Premissas!$B$9,Premissas!$B$14,IF(N9<Premissas!$B$10,Premissas!$B$15,IF(N9<Premissas!$B$11,Premissas!$B$16,IF(N9<Premissas!$B$12,Premissas!$B$17,Premissas!$B$18))))) | Q9: =IFERROR(P9/Premissas!$B$4,0)
A10: 7 | B10: 409 | C10: RECEBIMENTO | D10: 251240 | E10: Gildo Antonio Barbosa | F10: 3278 | G10: 39.72 | H10: 83 | I10: 25 | J10: GPA | K10: =IF(I10<>"",I10,IFERROR(INDEX(Base!$I:$I,MATCH(1,(Base!$C:$C=C10)*(Base!$I:$I<>""),0)),0)) | L10: =IF(AND(I10="",K10>0),"SIM","NÃO") | M10: =IF(ISNUMBER(SEARCH("SEPARA",UPPER(C10))),"NÃO","SIM") | N10: =IFERROR(H10/K10,0) | O10: =IF(M10="NÃO","EXCLUÍDO",IF(N10<Premissas!$B$8,"< 1,00",IF(N10<Premissas!$B$9,"1,00 – 1,19",IF(N10<Premissas!$B$10,"1,20 – 1,39",IF(N10<Premissas!$B$11,"1,40 – 1,59",IF(N10<Premissas!$B$12,"1,60 – 1,99","≥ 2,00")))))) | P10: =IF(OR(M10="NÃO",N10<Premissas!$B$8),Premissas!$B$13,IF(N10<Premissas!$B$9,Premissas!$B$14,IF(N10<Premissas!$B$10,Premissas!$B$15,IF(N10<Premissas!$B$11,Premissas!$B$16,IF(N10<Premissas!$B$12,Premissas!$B$17,Premissas!$B$18))))) | Q10: =IFERROR(P10/Premissas!$B$4,0)
A11: 7 | B11: 409 | C11: CARREGAMENTO | D11: 255199 | E11: Gilberton Santana De Moura | F11: 344 | G11: 7.68 | H11: 45 | I11: 24 | J11: GPA | K11: =IF(I11<>"",I11,IFERROR(INDEX(Base!$I:$I,MATCH(1,(Base!$C:$C=C11)*(Base!$I:$I<>""),0)),0)) | L11: =IF(AND(I11="",K11>0),"SIM","NÃO") | M11: =IF(ISNUMBER(SEARCH("SEPARA",UPPER(C11))),"NÃO","SIM") | N11: =IFERROR(H11/K11,0) | O11: =IF(M11="NÃO","EXCLUÍDO",IF(N11<Premissas!$B$8,"< 1,00",IF(N11<Premissas!$B$9,"1,00 – 1,19",IF(N11<Premissas!$B$10,"1,20 – 1,39",IF(N11<Premissas!$B$11,"1,40 – 1,59",IF(N11<Premissas!$B$12,"1,60 – 1,99","≥ 2,00")))))) | P11: =IF(OR(M11="NÃO",N11<Premissas!$B$8),Premissas!$B$13,IF(N11<Premissas!$B$9,Premissas!$B$14,IF(N11<Premissas!$B$10,Premissas!$B$15,IF(N11<Premissas!$B$11,Premissas!$B$16,IF(N11<Premissas!$B$12,Premissas!$B$17,Premissas!$B$18))))) | Q11: =IFERROR(P11/Premissas!$B$4,0)
A12: 7 | B12: 409 | C12: ATIVIDADE OP. EMP. | D12: 264318 | E12: Flavio Soares Da Silva | F12: 2828 | G12: 66.5 | H12: 43 | I12: 25 | J12: GPA | K12: =IF(I12<>"",I12,IFERROR(INDEX(Base!$I:$I,MATCH(1,(Base!$C:$C=C12)*(Base!$I:$I<>""),0)),0)) | L12: =IF(AND(I12="",K12>0),"SIM","NÃO") | M12: =IF(ISNUMBER(SEARCH("SEPARA",UPPER(C12))),"NÃO","SIM") | N12: =IFERROR(H12/K12,0) | O12: =IF(M12="NÃO","EXCLUÍDO",IF(N12<Premissas!$B$8,"< 1,00",IF(N12<Premissas!$B$9,"1,00 – 1,19",IF(N12<Premissas!$B$10,"1,20 – 1,39",IF(N12<Premissas!$B$11,"1,40 – 1,59",IF(N12<Premissas!$B$12,"1,60 – 1,99","≥ 2,00")))))) | P12: =IF(OR(M12="NÃO",N12<Premissas!$B$8),Premissas!$B$13,IF(N12<Premissas!$B$9,Premissas!$B$14,IF(N12<Premissas!$B$10,Premissas!$B$15,IF(N12<Premissas!$B$11,Premissas!$B$16,IF(N12<Premissas!$B$12,Premissas!$B$17,Premissas!$B$18))))) | Q12: =IFERROR(P12/Premissas!$B$4,0)
A13: 7 | B13: 409 | C13: SEPARACAO | D13: 264318 | E13: Flavio Soares Da Silva | F13: 714 | G13: 3.65 | H13: 196 | I13: 105 | J13: GPA | K13: =IF(I13<>"",I13,IFERROR(INDEX(Base!$I:$I,MATCH(1,(Base!$C:$C=C13)*(Base!$I:$I<>""),0)),0)) | L13: =IF(AND(I13="",K13>0),"SIM","NÃO") | M13: =IF(ISNUMBER(SEARCH("SEPARA",UPPER(C13))),"NÃO","SIM") | N13: =IFERROR(H13/K13,0) | O13: =IF(M13="NÃO","EXCLUÍDO",IF(N13<Premissas!$B$8,"< 1,00",IF(N13<Premissas!$B$9,"1,00 – 1,19",IF(N13<Premissas!$B$10,"1,20 – 1,39",IF(N13<Premissas!$B$11,"1,40 – 1,59",IF(N13<Premissas!$B$12,"1,60 – 1,99","≥ 2,00")))))) | P13: =IF(OR(M13="NÃO",N13<Premissas!$B$8),Premissas!$B$13,IF(N13<Premissas!$B$9,Premissas!$B$14,IF(N13<Premissas!$B$10,Premissas!$B$15,IF(N13<Premissas!$B$11,Premissas!$B$16,IF(N13<Premissas!$B$12,Premissas!$B$17,Premissas!$B$18))))) | Q13: =IFERROR(P13/Premissas!$B$4,0)
... A2091: 8 | B2091: 1942 | C2091: ATIVIDADE OP. EMP. | D2091: 85456 | E2091: GENIVALDO MANOEL | F2091: 1186 | G2091: 93.17 | H2091: 13 | I2091: 20 | J2091: GPA | K2091: =IF(I2091<>"",I2091,IFERROR(INDEX(Base!$I:$I,MATCH(1,(Base!$C:$C=C2091)*(Base!$I:$I<>""),0)),0)) | L2091: =IF(AND(I2091="",K2091>0),"SIM","NÃO") | M2091: =IF(ISNUMBER(SEARCH("SEPARA",UPPER(C2091))),"NÃO","SIM") | N2091: =IFERROR(H2091/K2091,0) | O2091: =IF(M2091="NÃO","EXCLUÍDO",IF(N2091<Premissas!$B$8,"< 1,00",IF(N2091<Premissas!$B$9,"1,00 – 1,19",IF(N2091<Premissas!$B$10,"1,20 – 1,39",IF(N2091<Premissas!$B$11,"1,40 – 1,59",IF(N2091<Premissas!$B$12,"1,60 – 1,99","≥ 2,00")))))) | P2091: =IF(OR(M2091="NÃO",N2091<Premissas!$B$8),Premissas!$B$13,IF(N2091<Premissas!$B$9,Premissas!$B$14,IF(N2091<Premissas!$B$10,Premissas!$B$15,IF(N2091<Premissas!$B$11,Premissas!$B$16,IF(N2091<Premissas!$B$12,Premissas!$B$17,Premissas!$B$18))))) | Q2091: =IFERROR(P2091/Premissas!$B$4,0)
A2092: 8 | B2092: 409 | C2092: ATIVIDADE OP. EMP. | D2092: 182403 | E2092: Reginaldo Alves Araujo | F2092: 2378 | G2092: 63.7 | H2092: 37 | I2092: 25 | J2092: GPA | K2092: =IF(I2092<>"",I2092,IFERROR(INDEX(Base!$I:$I,MATCH(1,(Base!$C:$C=C2092)*(Base!$I:$I<>""),0)),0)) | L2092: =IF(AND(I2092="",K2092>0),"SIM","NÃO") | M2092: =IF(ISNUMBER(SEARCH("SEPARA",UPPER(C2092))),"NÃO","SIM") | N2092: =IFERROR(H2092/K2092,0) | O2092: =IF(M2092="NÃO","EXCLUÍDO",IF(N2092<Premissas!$B$8,"< 1,00",IF(N2092<Premissas!$B$9,"1,00 – 1,19",IF(N2092<Premissas!$B$10,"1,20 – 1,39",IF(N2092<Premissas!$B$11,"1,40 – 1,59",IF(N2092<Premissas!$B$12,"1,60 – 1,99","≥ 2,00")))))) | P2092: =IF(OR(M2092="NÃO",N2092<Premissas!$B$8),Premissas!$B$13,IF(N2092<Premissas!$B$9,Premissas!$B$14,IF(N2092<Premissas!$B$10,Premissas!$B$15,IF(N2092<Premissas!$B$11,Premissas!$B$16,IF(N2092<Premissas!$B$12,Premissas!$B$17,Premissas!$B$18))))) | Q2092: =IFERROR(P2092/Premissas!$B$4,0)
A2093: 8 | B2093: 409 | C2093: RECEBIMENTO | D2093: 182403 | E2093: Reginaldo Alves Araujo | F2093: 1 | G2093: 0.17 | H2093: 6 | I2093: 25 | J2093: GPA | K2093: =IF(I2093<>"",I2093,IFERROR(INDEX(Base!$I:$I,MATCH(1,(Base!$C:$C=C2093)*(Base!$I:$I<>""),0)),0)) | L2093: =IF(AND(I2093="",K2093>0),"SIM","NÃO") | M2093: =IF(ISNUMBER(SEARCH("SEPARA",UPPER(C2093))),"NÃO","SIM") | N2093: =IFERROR(H2093/K2093,0) | O2093: =IF(M2093="NÃO","EXCLUÍDO",IF(N2093<Premissas!$B$8,"< 1,00",IF(N2093<Premissas!$B$9,"1,00 – 1,19",IF(N2093<Premissas!$B$10,"1,20 – 1,39",IF(N2093<Premissas!$B$11,"1,40 – 1,59",IF(N2093<Premissas!$B$12,"1,60 – 1,99","≥ 2,00")))))) | P2093: =IF(OR(M2093="NÃO",N2093<Premissas!$B$8),Premissas!$B$13,IF(N2093<Premissas!$B$9,Premissas!$B$14,IF(N2093<Premissas!$B$10,Premissas!$B$15,IF(N2093<Premissas!$B$11,Premissas!$B$16,IF(N2093<Premissas!$B$12,Premissas!$B$17,Premissas!$B$18))))) | Q2093: =IFERROR(P2093/Premissas!$B$4,0)
A2094: 8 | B2094: 409 | C2094: ATIVIDADE OP. EMP. | D2094: 245370 | E2094: Carlos Alberto Da Luz Teixeira | F2094: 1847 | G2094: 61.46 | H2094: 30 | I2094: 25 | J2094: GPA | K2094: =IF(I2094<>"",I2094,IFERROR(INDEX(Base!$I:$I,MATCH(1,(Base!$C:$C=C2094)*(Base!$I:$I<>""),0)),0)) | L2094: =IF(AND(I2094="",K2094>0),"SIM","NÃO") | M2094: =IF(ISNUMBER(SEARCH("SEPARA",UPPER(C2094))),"NÃO","SIM") | N2094: =IFERROR(H2094/K2094,0) | O2094: =IF(M2094="NÃO","EXCLUÍDO",IF(N2094<Premissas!$B$8,"< 1,00",IF(N2094<Premissas!$B$9,"1,00 – 1,19",IF(N2094<Premissas!$B$10,"1,20 – 1,39",IF(N2094<Premissas!$B$11,"1,40 – 1,59",IF(N2094<Premissas!$B$12,"1,60 – 1,99","≥ 2,00")))))) | P2094: =IF(OR(M2094="NÃO",N2094<Premissas!$B$8),Premissas!$B$13,IF(N2094<Premissas!$B$9,Premissas!$B$14,IF(N2094<Premissas!$B$10,Premissas!$B$15,IF(N2094<Premissas!$B$11,Premissas!$B$16,IF(N2094<Premissas!$B$12,Premissas!$B$17,Premissas!$B$18))))) | Q2094: =IFERROR(P2094/Premissas!$B$4,0)
A2095: 8 | B2095: 409 | C2095: CARREGAMENTO | D2095: 250187 | E2095: Marcio Da Silva Rodrigues | F2095: 31 | G2095: 0.38 | H2095: 82 | I2095: 24 | J2095: GPA | K2095: =IF(I2095<>"",I2095,IFERROR(INDEX(Base!$I:$I,MATCH(1,(Base!$C:$C=C2095)*(Base!$I:$I<>""),0)),0)) | L2095: =IF(AND(I2095="",K2095>0),"SIM","NÃO") | M2095: =IF(ISNUMBER(SEARCH("SEPARA",UPPER(C2095))),"NÃO","SIM") | N2095: =IFERROR(H2095/K2095,0) | O2095: =IF(M2095="NÃO","EXCLUÍDO",IF(N2095<Premissas!$B$8,"< 1,00",IF(N2095<Premissas!$B$9,"1,00 – 1,19",IF(N2095<Premissas!$B$10,"1,20 – 1,39",IF(N2095<Premissas!$B$11,"1,40 – 1,59",IF(N2095<Premissas!$B$12,"1,60 – 1,99","≥ 2,00")))))) | P2095: =IF(OR(M2095="NÃO",N2095<Premissas!$B$8),Premissas!$B$13,IF(N2095<Premissas!$B$9,Premissas!$B$14,IF(N2095<Premissas!$B$10,Premissas!$B$15,IF(N2095<Premissas!$B$11,Premissas!$B$16,IF(N2095<Premissas!$B$12,Premissas!$B$17,Premissas!$B$18))))) | Q2095: =IFERROR(P2095/Premissas!$B$4,0)
A2096: 8 | B2096: 409 | C2096: RECEBIMENTO | D2096: 250187 | E2096: Marcio Da Silva Rodrigues | F2096: 1249 | G2096: 29.61 | H2096: 42 | I2096: 25 | J2096: GPA | K2096: =IF(I2096<>"",I2096,IFERROR(INDEX(Base!$I:$I,MATCH(1,(Base!$C:$C=C2096)*(Base!$I:$I<>""),0)),0)) | L2096: =IF(AND(I2096="",K2096>0),"SIM","NÃO") | M2096: =IF(ISNUMBER(SEARCH("SEPARA",UPPER(C2096))),"NÃO","SIM") | N2096: =IFERROR(H2096/K2096,0) | O2096: =IF(M2096="NÃO","EXCLUÍDO",IF(N2096<Premissas!$B$8,"< 1,00",IF(N2096<Premissas!$B$9,"1,00 – 1,19",IF(N2096<Premissas!$B$10,"1,20 – 1,39",IF(N2096<Premissas!$B$11,"1,40 – 1,59",IF(N2096<Premissas!$B$12,"1,60 – 1,99","≥ 2,00")))))) | P2096: =IF(OR(M2096="NÃO",N2096<Premissas!$B$8),Premissas!$B$13,IF(N2096<Premissas!$B$9,Premissas!$B$14,IF(N2096<Premissas!$B$10,Premissas!$B$15,IF(N2096<Premissas!$B$11,Premissas!$B$16,IF(N2096<Premissas!$B$12,Premissas!$B$17,Premissas!$B$18))))) | Q2096: =IFERROR(P2096/Premissas!$B$4,0)
A2097: 8 | B2097: 409 | C2097: PUXADA RECEB | D2097: 250896 | E2097: Hugo Clementino Nunes | F2097: 5 | G2097: 1.42 | H2097: 4 | I2097: 22 | J2097: GPA | K2097: =IF(I2097<>"",I2097,IFERROR(INDEX(Base!$I:$I,MATCH(1,(Base!$C:$C=C2097)*(Base!$I:$I<>""),0)),0)) | L2097: =IF(AND(I2097="",K2097>0),"SIM","NÃO") | M2097: =IF(ISNUMBER(SEARCH("SEPARA",UPPER(C2097))),"NÃO","SIM") | N2097: =IFERROR(H2097/K2097,0) | O2097: =IF(M2097="NÃO","EXCLUÍDO",IF(N2097<Premissas!$B$8,"< 1,00",IF(N2097<Premissas!$B$9,"1,00 – 1,19",IF(N2097<Premissas!$B$10,"1,20 – 1,39",IF(N2097<Premissas!$B$11,"1,40 – 1,59",IF(N2097<Premissas!$B$12,"1,60 – 1,99","≥ 2,00")))))) | P2097: =IF(OR(M2097="NÃO",N2097<Premissas!$B$8),Premissas!$B$13,IF(N2097<Premissas!$B$9,Premissas!$B$14,IF(N2097<Premissas!$B$10,Premissas!$B$15,IF(N2097<Premissas!$B$11,Premissas!$B$16,IF(N2097<Premissas!$B$12,Premissas!$B$17,Premissas!$B$18))))) | Q2097: =IFERROR(P2097/Premissas!$B$4,0)
A2098: 8 | B2098: 409 | C2098: PUXADA RECEB | D2098: 251239 | E2098: Mauricio Rodrigues | F2098: 31 | G2098: 13.25 | H2098: 2 | I2098: 22 | J2098: GPA | K2098: =IF(I2098<>"",I2098,IFERROR(INDEX(Base!$I:$I,MATCH(1,(Base!$C:$C=C2098)*(Base!$I:$I<>""),0)),0)) | L2098: =IF(AND(I2098="",K2098>0),"SIM","NÃO") | M2098: =IF(ISNUMBER(SEARCH("SEPARA",UPPER(C2098))),"NÃO","SIM") | N2098: =IFERROR(H2098/K2098,0) | O2098: =IF(M2098="NÃO","EXCLUÍDO",IF(N2098<Premissas!$B$8,"< 1,00",IF(N2098<Premissas!$B$9,"1,00 – 1,19",IF(N2098<Premissas!$B$10,"1,20 – 1,39",IF(N2098<Premissas!$B$11,"1,40 – 1,59",IF(N2098<Premissas!$B$12,"1,60 – 1,99","≥ 2,00")))))) | P2098: =IF(OR(M2098="NÃO",N2098<Premissas!$B$8),Premissas!$B$13,IF(N2098<Premissas!$B$9,Premissas!$B$14,IF(N2098<Premissas!$B$10,Premissas!$B$15,IF(N2098<Premissas!$B$11,Premissas!$B$16,IF(N2098<Premissas!$B$12,Premissas!$B$17,Premissas!$B$18))))) | Q2098: =IFERROR(P2098/Premissas!$B$4,0)
A2099: 8 | B2099: 409 | C2099: RECEBIMENTO | D2099: 251239 | E2099: Mauricio Rodrigues | F2099: 1 | G2099: 1.15 | H2099: 1 | I2099: 25 | J2099: GPA | K2099: =IF(I2099<>"",I2099,IFERROR(INDEX(Base!$I:$I,MATCH(1,(Base!$C:$C=C2099)*(Base!$I:$I<>""),0)),0)) | L2099: =IF(AND(I2099="",K2099>0),"SIM","NÃO") | M2099: =IF(ISNUMBER(SEARCH("SEPARA",UPPER(C2099))),"NÃO","SIM") | N2099: =IFERROR(H2099/K2099,0) | O2099: =IF(M2099="NÃO","EXCLUÍDO",IF(N2099<Premissas!$B$8,"< 1,00",IF(N2099<Premissas!$B$9,"1,00 – 1,19",IF(N2099<Premissas!$B$10,"1,20 – 1,39",IF(N2099<Premissas!$B$11,"1,40 – 1,59",IF(N2099<Premissas!$B$12,"1,60 – 1,99","≥ 2,00")))))) | P2099: =IF(OR(M2099="NÃO",N2099<Premissas!$B$8),Premissas!$B$13,IF(N2099<Premissas!$B$9,Premissas!$B$14,IF(N2099<Premissas!$B$10,Premissas!$B$15,IF(N2099<Premissas!$B$11,Premissas!$B$16,IF(N2099<Premissas!$B$12,Premissas!$B$17,Premissas!$B$18))))) | Q2099: =IFERROR(P2099/Premissas!$B$4,0)
A2100: 8 | B2100: 409 | C2100: PUXADA RECEB | D2100: 251240 | E2100: Gildo Antonio Barbosa | F2100: 56 | G2100: 1.9 | H2100: 29 | I2100: 22 | J2100: GPA | K2100: =IF(I2100<>"",I2100,IFERROR(INDEX(Base!$I:$I,MATCH(1,(Base!$C:$C=C2100)*(Base!$I:$I<>""),0)),0)) | L2100: =IF(AND(I2100="",K2100>0),"SIM","NÃO") | M2100: =IF(ISNUMBER(SEARCH("SEPARA",UPPER(C2100))),"NÃO","SIM") | N2100: =IFERROR(H2100/K2100,0) | O2100: =IF(M2100="NÃO","EXCLUÍDO",IF(N2100<Premissas!$B$8,"< 1,00",IF(N2100<Premissas!$B$9,"1,00 – 1,19",IF(N2100<Premissas!$B$10,"1,20 – 1,39",IF(N2100<Premissas!$B$11,"1,40 – 1,59",IF(N2100<Premissas!$B$12,"1,60 – 1,99","≥ 2,00")))))) | P2100: =IF(OR(M2100="NÃO",N2100<Premissas!$B$8),Premissas!$B$13,IF(N2100<Premissas!$B$9,Premissas!$B$14,IF(N2100<Premissas!$B$10,Premissas!$B$15,IF(N2100<Premissas!$B$11,Premissas!$B$16,IF(N2100<Premissas!$B$12,Premissas!$B$17,Premissas!$B$18))))) | Q2100: =IFERROR(P2100/Premissas!$B$4,0)
A2101: 8 | B2101: 409 | C2101: RECEBIMENTO | D2101: 251240 | E2101: Gildo Antonio Barbosa | F2101: 2743 | G2101: 36.99 | H2101: 74 | I2101: 25 | J2101: GPA | K2101: =IF(I2101<>"",I2101,IFERROR(INDEX(Base!$I:$I,MATCH(1,(Base!$C:$C=C2101)*(Base!$I:$I<>""),0)),0)) | L2101: =IF(AND(I2101="",K2101>0),"SIM","NÃO") | M2101: =IF(ISNUMBER(SEARCH("SEPARA",UPPER(C2101))),"NÃO","SIM") | N2101: =IFERROR(H2101/K2101,0) | O2101: =IF(M2101="NÃO","EXCLUÍDO",IF(N2101<Premissas!$B$8,"< 1,00",IF(N2101<Premissas!$B$9,"1,00 – 1,19",IF(N2101<Premissas!$B$10,"1,20 – 1,39",IF(N2101<Premissas!$B$11,"1,40 – 1,59",IF(N2101<Premissas!$B$12,"1,60 – 1,99","≥ 2,00")))))) | P2101: =IF(OR(M2101="NÃO",N2101<Premissas!$B$8),Premissas!$B$13,IF(N2101<Premissas!$B$9,Premissas!$B$14,IF(N2101<Premissas!$B$10,Premissas!$B$15,IF(N2101<Premissas!$B$11,Premissas!$B$16,IF(N2101<Premissas!$B$12,Premissas!$B$17,Premissas!$B$18))))) | Q2101: =IFERROR(P2101/Premissas!$B$4,0)
A2102: 8 | B2102: 409 | C2102: CARREGAMENTO | D2102: 255199 | E2102: Gilberton Santana De Moura | F2102: 161 | G2102: 4.13 | H2102: 39 | I2102: 24 | J2102: GPA | K2102: =IF(I2102<>"",I2102,IFERROR(INDEX(Base!$I:$I,MATCH(1,(Base!$C:$C=C2102)*(Base!$I:$I<>""),0)),0)) | L2102: =IF(AND(I2102="",K2102>0),"SIM","NÃO") | M2102: =IF(ISNUMBER(SEARCH("SEPARA",UPPER(C2102))),"NÃO","SIM") | N2102: =IFERROR(H2102/K2102,0) | O2102: =IF(M2102="NÃO","EXCLUÍDO",IF(N2102<Premissas!$B$8,"< 1,00",IF(N2102<Premissas!$B$9,"1,00 – 1,19",IF(N2102<Premissas!$B$10,"1,20 – 1,39",IF(N2102<Premissas!$B$11,"1,40 – 1,59",IF(N2102<Premissas!$B$12,"1,60 – 1,99","≥ 2,00")))))) | P2102: =IF(OR(M2102="NÃO",N2102<Premissas!$B$8),Premissas!$B$13,IF(N2102<Premissas!$B$9,Premissas!$B$14,IF(N2102<Premissas!$B$10,Premissas!$B$15,IF(N2102<Premissas!$B$11,Premissas!$B$16,IF(N2102<Premissas!$B$12,Premissas!$B$17,Premissas!$B$18))))) | Q2102: =IFERROR(P2102/Premissas!$B$4,0)
A2103: 8 | B2103: 409 | C2103: ATIVIDADE OP. EMP. | D2103: 264318 | E2103: Flavio Soares Da Silva | F2103: 1467 | G2103: 34.83 | H2103: 42 | I2103: 25 | J2103: GPA | K2103: =IF(I2103<>"",I2103,IFERROR(INDEX(Base!$I:$I,MATCH(1,(Base!$C:$C=C2103)*(Base!$I:$I<>""),0)),0)) | L2103: =IF(AND(I2103="",K2103>0),"SIM","NÃO") | M2103: =IF(ISNUMBER(SEARCH("SEPARA",UPPER(C2103))),"NÃO","SIM") | N2103: =IFERROR(H2103/K2103,0) | O2103: =IF(M2103="NÃO","EXCLUÍDO",IF(N2103<Premissas!$B$8,"< 1,00",IF(N2103<Premissas!$B$9,"1,00 – 1,19",IF(N2103<Premissas!$B$10,"1,20 – 1,39",IF(N2103<Premissas!$B$11,"1,40 – 1,59",IF(N2103<Premissas!$B$12,"1,60 – 1,99","≥ 2,00")))))) | P2103: =IF(OR(M2103="NÃO",N2103<Premissas!$B$8),Premissas!$B$13,IF(N2103<Premissas!$B$9,Premissas!$B$14,IF(N2103<Premissas!$B$10,Premissas!$B$15,IF(N2103<Premissas!$B$11,Premissas!$B$16,IF(N2103<Premissas!$B$12,Premissas!$B$17,Premissas!$B$18))))) | Q2103: =IFERROR(P2103/Premissas!$B$4,0)
... A2945: 8 | B2945: 1965 | C2945: CARREGAMENTO | D2945: 2958732 | E2945: Gilvana Oliveira De Araujo | F2945: 192 | G2945: 9.96 | H2945: 19 | I2945: 0 | J2945: GPA | K2945: =IF(I2945<>"",I2945,IFERROR(INDEX(Base!$I:$I,MATCH(1,(Base!$C:$C=C2945)*(Base!$I:$I<>""),0)),0)) | L2945: =IF(AND(I2945="",K2945>0),"SIM","NÃO") | M2945: =IF(ISNUMBER(SEARCH("SEPARA",UPPER(C2945))),"NÃO","SIM") | N2945: =IFERROR(H2945/K2945,0) | O2945: =IF(M2945="NÃO","EXCLUÍDO",IF(N2945<Premissas!$B$8,"< 1,00",IF(N2945<Premissas!$B$9,"1,00 – 1,19",IF(N2945<Premissas!$B$10,"1,20 – 1,39",IF(N2945<Premissas!$B$11,"1,40 – 1,59",IF(N2945<Premissas!$B$12,"1,60 – 1,99","≥ 2,00")))))) | P2945: =IF(OR(M2945="NÃO",N2945<Premissas!$B$8),Premissas!$B$13,IF(N2945<Premissas!$B$9,Premissas!$B$14,IF(N2945<Premissas!$B$10,Premissas!$B$15,IF(N2945<Premissas!$B$11,Premissas!$B$16,IF(N2945<Premissas!$B$12,Premissas!$B$17,Premissas!$B$18))))) | Q2945: =IFERROR(P2945/Premissas!$B$4,0)
A2946: 8 | B2946: 1965 | C2946: SEPARACAO | D2946: 2991799 | E2946: Gustavo De Mello Dos Santos | F2946: 297 | G2946: 8.07 | H2946: 37 | J2946: GPA | K2946: =IF(I2946<>"",I2946,IFERROR(INDEX(Base!$I:$I,MATCH(1,(Base!$C:$C=C2946)*(Base!$I:$I<>""),0)),0)) | L2946: =IF(AND(I2946="",K2946>0),"SIM","NÃO") | M2946: =IF(ISNUMBER(SEARCH("SEPARA",UPPER(C2946))),"NÃO","SIM") | N2946: =IFERROR(H2946/K2946,0) | O2946: =IF(M2946="NÃO","EXCLUÍDO",IF(N2946<Premissas!$B$8,"< 1,00",IF(N2946<Premissas!$B$9,"1,00 – 1,19",IF(N2946<Premissas!$B$10,"1,20 – 1,39",IF(N2946<Premissas!$B$11,"1,40 – 1,59",IF(N2946<Premissas!$B$12,"1,60 – 1,99","≥ 2,00")))))) | P2946: =IF(OR(M2946="NÃO",N2946<Premissas!$B$8),Premissas!$B$13,IF(N2946<Premissas!$B$9,Premissas!$B$14,IF(N2946<Premissas!$B$10,Premissas!$B$15,IF(N2946<Premissas!$B$11,Premissas!$B$16,IF(N2946<Premissas!$B$12,Premissas!$B$17,Premissas!$B$18))))) | Q2946: =IFERROR(P2946/Premissas!$B$4,0)
A2947: 8 | B2947: 1965 | C2947: RECEBIMENTO | D2947: 30307 | E2947: MARIA VANDA DOS ANJOS CRUZ | F2947: 153 | G2947: 20.01 | H2947: 8 | I2947: 0 | J2947: GPA | K2947: =IF(I2947<>"",I2947,IFERROR(INDEX(Base!$I:$I,MATCH(1,(Base!$C:$C=C2947)*(Base!$I:$I<>""),0)),0)) | L2947: =IF(AND(I2947="",K2947>0),"SIM","NÃO") | M2947: =IF(ISNUMBER(SEARCH("SEPARA",UPPER(C2947))),"NÃO","SIM") | N2947: =IFERROR(H2947/K2947,0) | O2947: =IF(M2947="NÃO","EXCLUÍDO",IF(N2947<Premissas!$B$8,"< 1,00",IF(N2947<Premissas!$B$9,"1,00 – 1,19",IF(N2947<Premissas!$B$10,"1,20 – 1,39",IF(N2947<Premissas!$B$11,"1,40 – 1,59",IF(N2947<Premissas!$B$12,"1,60 – 1,99","≥ 2,00")))))) | P2947: =IF(OR(M2947="NÃO",N2947<Premissas!$B$8),Premissas!$B$13,IF(N2947<Premissas!$B$9,Premissas!$B$14,IF(N2947<Premissas!$B$10,Premissas!$B$15,IF(N2947<Premissas!$B$11,Premissas!$B$16,IF(N2947<Premissas!$B$12,Premissas!$B$17,Premissas!$B$18))))) | Q2947: =IFERROR(P2947/Premissas!$B$4,0)
A2948: 8 | B2948: 1965 | C2948: ATIVIDADE OP. EMP. | D2948: 308129 | E2948: Silvio Rodrigues Da Macena | F2948: 57 | G2948: 9.52 | H2948: 6 | I2948: 0 | J2948: GPA | K2948: =IF(I2948<>"",I2948,IFERROR(INDEX(Base!$I:$I,MATCH(1,(Base!$C:$C=C2948)*(Base!$I:$I<>""),0)),0)) | L2948: =IF(AND(I2948="",K2948>0),"SIM","NÃO") | M2948: =IF(ISNUMBER(SEARCH("SEPARA",UPPER(C2948))),"NÃO","SIM") | N2948: =IFERROR(H2948/K2948,0) | O2948: =IF(M2948="NÃO","EXCLUÍDO",IF(N2948<Premissas!$B$8,"< 1,00",IF(N2948<Premissas!$B$9,"1,00 – 1,19",IF(N2948<Premissas!$B$10,"1,20 – 1,39",IF(N2948<Premissas!$B$11,"1,40 – 1,59",IF(N2948<Premissas!$B$12,"1,60 – 1,99","≥ 2,00")))))) | P2948: =IF(OR(M2948="NÃO",N2948<Premissas!$B$8),Premissas!$B$13,IF(N2948<Premissas!$B$9,Premissas!$B$14,IF(N2948<Premissas!$B$10,Premissas!$B$15,IF(N2948<Premissas!$B$11,Premissas!$B$16,IF(N2948<Premissas!$B$12,Premissas!$B$17,Premissas!$B$18))))) | Q2948: =IFERROR(P2948/Premissas!$B$4,0)
A2949: 8 | B2949: 1965 | C2949: RECEBIMENTO | D2949: 308129 | E2949: Silvio Rodrigues Da Macena | F2949: 1 | G2949: 0.46 | H2949: 2 | I2949: 0 | J2949: GPA | K2949: =IF(I2949<>"",I2949,IFERROR(INDEX(Base!$I:$I,MATCH(1,(Base!$C:$C=C2949)*(Base!$I:$I<>""),0)),0)) | L2949: =IF(AND(I2949="",K2949>0),"SIM","NÃO") | M2949: =IF(ISNUMBER(SEARCH("SEPARA",UPPER(C2949))),"NÃO","SIM") | N2949: =IFERROR(H2949/K2949,0) | O2949: =IF(M2949="NÃO","EXCLUÍDO",IF(N2949<Premissas!$B$8,"< 1,00",IF(N2949<Premissas!$B$9,"1,00 – 1,19",IF(N2949<Premissas!$B$10,"1,20 – 1,39",IF(N2949<Premissas!$B$11,"1,40 – 1,59",IF(N2949<Premissas!$B$12,"1,60 – 1,99","≥ 2,00")))))) | P2949: =IF(OR(M2949="NÃO",N2949<Premissas!$B$8),Premissas!$B$13,IF(N2949<Premissas!$B$9,Premissas!$B$14,IF(N2949<Premissas!$B$10,Premissas!$B$15,IF(N2949<Premissas!$B$11,Premissas!$B$16,IF(N2949<Premissas!$B$12,Premissas!$B$17,Premissas!$B$18))))) | Q2949: =IFERROR(P2949/Premissas!$B$4,0)
A2950: 8 | B2950: 1965 | C2950: ATIVIDADE OP. EMP. | D2950: 308965 | E2950: ANDRE FERREIRA APOLINARIO | F2950: 961 | G2950: 104.26 | H2950: 9 | I2950: 0 | J2950: GPA | K2950: =IF(I2950<>"",I2950,IFERROR(INDEX(Base!$I:$I,MATCH(1,(Base!$C:$C=C2950)*(Base!$I:$I<>""),0)),0)) | L2950: =IF(AND(I2950="",K2950>0),"SIM","NÃO") | M2950: =IF(ISNUMBER(SEARCH("SEPARA",UPPER(C2950))),"NÃO","SIM") | N2950: =IFERROR(H2950/K2950,0) | O2950: =IF(M2950="NÃO","EXCLUÍDO",IF(N2950<Premissas!$B$8,"< 1,00",IF(N2950<Premissas!$B$9,"1,00 – 1,19",IF(N2950<Premissas!$B$10,"1,20 – 1,39",IF(N2950<Premissas!$B$11,"1,40 – 1,59",IF(N2950<Premissas!$B$12,"1,60 – 1,99","≥ 2,00")))))) | P2950: =IF(OR(M2950="NÃO",N2950<Premissas!$B$8),Premissas!$B$13,IF(N2950<Premissas!$B$9,Premissas!$B$14,IF(N2950<Premissas!$B$10,Premissas!$B$15,IF(N2950<Premissas!$B$11,Premissas!$B$16,IF(N2950<Premissas!$B$12,Premissas!$B$17,Premissas!$B$18))))) | Q2950: =IFERROR(P2950/Premissas!$B$4,0)
A2951: 8 | B2951: 1965 | C2951: RECEBIMENTO | D2951: 3155196 | E2951: CLAUDIO ROBERTO OTAVIO | F2951: 785 | G2951: 89.69 | H2951: 9 | I2951: 0 | J2951: GPA | K2951: =IF(I2951<>"",I2951,IFERROR(INDEX(Base!$I:$I,MATCH(1,(Base!$C:$C=C2951)*(Base!$I:$I<>""),0)),0)) | L2951: =IF(AND(I2951="",K2951>0),"SIM","NÃO") | M2951: =IF(ISNUMBER(SEARCH("SEPARA",UPPER(C2951))),"NÃO","SIM") | N2951: =IFERROR(H2951/K2951,0) | O2951: =IF(M2951="NÃO","EXCLUÍDO",IF(N2951<Premissas!$B$8,"< 1,00",IF(N2951<Premissas!$B$9,"1,00 – 1,19",IF(N2951<Premissas!$B$10,"1,20 – 1,39",IF(N2951<Premissas!$B$11,"1,40 – 1,59",IF(N2951<Premissas!$B$12,"1,60 – 1,99","≥ 2,00")))))) | P2951: =IF(OR(M2951="NÃO",N2951<Premissas!$B$8),Premissas!$B$13,IF(N2951<Premissas!$B$9,Premissas!$B$14,IF(N2951<Premissas!$B$10,Premissas!$B$15,IF(N2951<Premissas!$B$11,Premissas!$B$16,IF(N2951<Premissas!$B$12,Premissas!$B$17,Premissas!$B$18))))) | Q2951: =IFERROR(P2951/Premissas!$B$4,0)
A2952: 8 | B2952: 1965 | C2952: ATIVIDADE OP. EMP. | D2952: 316516 | E2952: EDMAR AGUIAR VIANA | F2952: 1909 | G2952: 177.75 | H2952: 11 | I2952: 0 | J2952: GPA | K2952: =IF(I2952<>"",I2952,IFERROR(INDEX(Base!$I:$I,MATCH(1,(Base!$C:$C=C2952)*(Base!$I:$I<>""),0)),0)) | L2952: =IF(AND(I2952="",K2952>0),"SIM","NÃO") | M2952: =IF(ISNUMBER(SEARCH("SEPARA",UPPER(C2952))),"NÃO","SIM") | N2952: =IFERROR(H2952/K2952,0) | O2952: =IF(M2952="NÃO","EXCLUÍDO",IF(N2952<Premissas!$B$8,"< 1,00",IF(N2952<Premissas!$B$9,"1,00 – 1,19",IF(N2952<Premissas!$B$10,"1,20 – 1,39",IF(N2952<Premissas!$B$11,"1,40 – 1,59",IF(N2952<Premissas!$B$12,"1,60 – 1,99","≥ 2,00")))))) | P2952: =IF(OR(M2952="NÃO",N2952<Premissas!$B$8),Premissas!$B$13,IF(N2952<Premissas!$B$9,Premissas!$B$14,IF(N2952<Premissas!$B$10,Premissas!$B$15,IF(N2952<Premissas!$B$11,Premissas!$B$16,IF(N2952<Premissas!$B$12,Premissas!$B$17,Premissas!$B$18))))) | Q2952: =IFERROR(P2952/Premissas!$B$4,0)
A2953: 8 | B2953: 1965 | C2953: ATIVIDADE OP. EMP. | D2953: 322452 | E2953: Givaldo Moreira Silva | F2953: 2709 | G2953: 159.88 | H2953: 17 | I2953: 0 | J2953: GPA | K2953: =IF(I2953<>"",I2953,IFERROR(INDEX(Base!$I:$I,MATCH(1,(Base!$C:$C=C2953)*(Base!$I:$I<>""),0)),0)) | L2953: =IF(AND(I2953="",K2953>0),"SIM","NÃO") | M2953: =IF(ISNUMBER(SEARCH("SEPARA",UPPER(C2953))),"NÃO","SIM") | N2953: =IFERROR(H2953/K2953,0) | O2953: =IF(M2953="NÃO","EXCLUÍDO",IF(N2953<Premissas!$B$8,"< 1,00",IF(N2953<Premissas!$B$9,"1,00 – 1,19",IF(N2953<Premissas!$B$10,"1,20 – 1,39",IF(N2953<Premissas!$B$11,"1,40 – 1,59",IF(N2953<Premissas!$B$12,"1,60 – 1,99","≥ 2,00")))))) | P2953: =IF(OR(M2953="NÃO",N2953<Premissas!$B$8),Premissas!$B$13,IF(N2953<Premissas!$B$9,Premissas!$B$14,IF(N2953<Premissas!$B$10,Premissas!$B$15,IF(N2953<Premissas!$B$11,Premissas!$B$16,IF(N2953<Premissas!$B$12,Premissas!$B$17,Premissas!$B$18))))) | Q2953: =IFERROR(P2953/Premissas!$B$4,0)
A2954: 8 | B2954: 1965 | C2954: CARREGAMENTO | D2954: 322452 | E2954: Givaldo Moreira Silva | F2954: 63 | G2954: 4.38 | H2954: 14 | I2954: 0 | J2954: GPA | K2954: =IF(I2954<>"",I2954,IFERROR(INDEX(Base!$I:$I,MATCH(1,(Base!$C:$C=C2954)*(Base!$I:$I<>""),0)),0)) | L2954: =IF(AND(I2954="",K2954>0),"SIM","NÃO") | M2954: =IF(ISNUMBER(SEARCH("SEPARA",UPPER(C2954))),"NÃO","SIM") | N2954: =IFERROR(H2954/K2954,0) | O2954: =IF(M2954="NÃO","EXCLUÍDO",IF(N2954<Premissas!$B$8,"< 1,00",IF(N2954<Premissas!$B$9,"1,00 – 1,19",IF(N2954<Premissas!$B$10,"1,20 – 1,39",IF(N2954<Premissas!$B$11,"1,40 – 1,59",IF(N2954<Premissas!$B$12,"1,60 – 1,99","≥ 2,00")))))) | P2954: =IF(OR(M2954="NÃO",N2954<Premissas!$B$8),Premissas!$B$13,IF(N2954<Premissas!$B$9,Premissas!$B$14,IF(N2954<Premissas!$B$10,Premissas!$B$15,IF(N2954<Premissas!$B$11,Premissas!$B$16,IF(N2954<Premissas!$B$12,Premissas!$B$17,Premissas!$B$18))))) | Q2954: =IFERROR(P2954/Premissas!$B$4,0)
A2955: 8 | B2955: 1965 | C2955: ATIVIDADE OP. EMP. | D2955: 324132 | E2955: ARIEL SOUZA OLIVEIRA | F2955: 1430 | G2955: 160.38 | H2955: 9 | I2955: 0 | J2955: GPA | K2955: =IF(I2955<>"",I2955,IFERROR(INDEX(Base!$I:$I,MATCH(1,(Base!$C:$C=C2955)*(Base!$I:$I<>""),0)),0)) | L2955: =IF(AND(I2955="",K2955>0),"SIM","NÃO") | M2955: =IF(ISNUMBER(SEARCH("SEPARA",UPPER(C2955))),"NÃO","SIM") | N2955: =IFERROR(H2955/K2955,0) | O2955: =IF(M2955="NÃO","EXCLUÍDO",IF(N2955<Premissas!$B$8,"< 1,00",IF(N2955<Premissas!$B$9,"1,00 – 1,19",IF(N2955<Premissas!$B$10,"1,20 – 1,39",IF(N2955<Premissas!$B$11,"1,40 – 1,59",IF(N2955<Premissas!$B$12,"1,60 – 1,99","≥ 2,00")))))) | P2955: =IF(OR(M2955="NÃO",N2955<Premissas!$B$8),Premissas!$B$13,IF(N2955<Premissas!$B$9,Premissas!$B$14,IF(N2955<Premissas!$B$10,Premissas!$B$15,IF(N2955<Premissas!$B$11,Premissas!$B$16,IF(N2955<Premissas!$B$12,Premissas!$B$17,Premissas!$B$18))))) | Q2955: =IFERROR(P2955/Premissas!$B$4,0)
A2956: 8 | B2956: 1965 | C2956: RECEBIMENTO | D2956: 3353583 | E2956: GILBERTO NOVAES DOS SANTOS | F2956: 1095 | G2956: 113.3 | H2956: 10 | I2956: 0 | J2956: GPA | K2956: =IF(I2956<>"",I2956,IFERROR(INDEX(Base!$I:$I,MATCH(1,(Base!$C:$C=C2956)*(Base!$I:$I<>""),0)),0)) | L2956: =IF(AND(I2956="",K2956>0),"SIM","NÃO") | M2956: =IF(ISNUMBER(SEARCH("SEPARA",UPPER(C2956))),"NÃO","SIM") | N2956: =IFERROR(H2956/K2956,0) | O2956: =IF(M2956="NÃO","EXCLUÍDO",IF(N2956<Premissas!$B$8,"< 1,00",IF(N2956<Premissas!$B$9,"1,00 – 1,19",IF(N2956<Premissas!$B$10,"1,20 – 1,39",IF(N2956<Premissas!$B$11,"1,40 – 1,59",IF(N2956<Premissas!$B$12,"1,60 – 1,99","≥ 2,00")))))) | P2956: =IF(OR(M2956="NÃO",N2956<Premissas!$B$8),Premissas!$B$13,IF(N2956<Premissas!$B$9,Premissas!$B$14,IF(N2956<Premissas!$B$10,Premissas!$B$15,IF(N2956<Premissas!$B$11,Premissas!$B$16,IF(N2956<Premissas!$B$12,Premissas!$B$17,Premissas!$B$18))))) | Q2956: =IFERROR(P2956/Premissas!$B$4,0)
A2957: 8 | B2957: 1965 | C2957: SEPARACAO | D2957: 3353583 | E2957: GILBERTO NOVAES DOS SANTOS | F2957: 61 | G2957: 0.84 | H2957: 73 | J2957: GPA | K2957: =IF(I2957<>"",I2957,IFERROR(INDEX(Base!$I:$I,MATCH(1,(Base!$C:$C=C2957)*(Base!$I:$I<>""),0)),0)) | L2957: =IF(AND(I2957="",K2957>0),"SIM","NÃO") | M2957: =IF(ISNUMBER(SEARCH("SEPARA",UPPER(C2957))),"NÃO","SIM") | N2957: =IFERROR(H2957/K2957,0) | O2957: =IF(M2957="NÃO","EXCLUÍDO",IF(N2957<Premissas!$B$8,"< 1,00",IF(N2957<Premissas!$B$9,"1,00 – 1,19",IF(N2957<Premissas!$B$10,"1,20 – 1,39",IF(N2957<Premissas!$B$11,"1,40 – 1,59",IF(N2957<Premissas!$B$12,"1,60 – 1,99","≥ 2,00")))))) | P2957: =IF(OR(M2957="NÃO",N2957<Premissas!$B$8),Premissas!$B$13,IF(N2957<Premissas!$B$9,Premissas!$B$14,IF(N2957<Premissas!$B$10,Premissas!$B$15,IF(N2957<Premissas!$B$11,Premissas!$B$16,IF(N2957<Premissas!$B$12,Premissas!$B$17,Premissas!$B$18))))) | Q2957: =IFERROR(P2957/Premissas!$B$4,0)
A2958: 8 | B2958: 1965 | C2958: CARREGAMENTO | D2958: 335416 | E2958: Dourivaldo Dias De Oliveira | F2958: 103 | G2958: 32.15 | H2958: 3 | I2958: 0 | J2958: GPA | K2958: =IF(I2958<>"",I2958,IFERROR(INDEX(Base!$I:$I,MATCH(1,(Base!$C:$C=C2958)*(Base!$I:$I<>""),0)),0)) | L2958: =IF(AND(I2958="",K2958>0),"SIM","NÃO") | M2958: =IF(ISNUMBER(SEARCH("SEPARA",UPPER(C2958))),"NÃO","SIM") | N2958: =IFERROR(H2958/K2958,0) | O2958: =IF(M2958="NÃO","EXCLUÍDO",IF(N2958<Premissas!$B$8,"< 1,00",IF(N2958<Premissas!$B$9,"1,00 – 1,19",IF(N2958<Premissas!$B$10,"1,20 – 1,39",IF(N2958<Premissas!$B$11,"1,40 – 1,59",IF(N2958<Premissas!$B$12,"1,60 – 1,99","≥ 2,00")))))) | P2958: =IF(OR(M2958="NÃO",N2958<Premissas!$B$8),Premissas!$B$13,IF(N2958<Premissas!$B$9,Premissas!$B$14,IF(N2958<Premissas!$B$10,Premissas!$B$15,IF(N2958<Premissas!$B$11,Premissas!$B$16,IF(N2958<Premissas!$B$12,Premissas!$B$17,Premissas!$B$18))))) | Q2958: =IFERROR(P2958/Premissas!$B$4,0)
...

Sheet Consolidado_HC
A1: USUARIO | B1: COLABORADOR | C1: CD_PRINCIPAL | D1: ATIVIDADES | E1: N_REGISTROS | F1: MELHOR_FATOR | G1: FATOR_MEDIO | H1: QTD_TOTAL | I1: HORAS_TOTAL | J1: FAIXA | K1: VALOR_MENSAL | L1: VALOR_DIARIO | M1: NO_TETO
A2: 442042 | B2: Acacio Attilio Chieregatte Braga | C2: 409 | D2: =IFERROR(TEXTJOIN(" | ",TRUE,UNIQUE(FILTER(Detalhe_Registro!$C:$C,(Detalhe_Registro!$D:$D=A2)*(Detalhe_Registro!$E:$E=B2)*(Detalhe_Registro!$M:$M="SIM")))),"") | E2: =COUNTIFS(Detalhe_Registro!$D:$D,A2,Detalhe_Registro!$E:$E,B2,Detalhe_Registro!$M:$M,"SIM") | F2: =IFERROR(MAXIFS(Detalhe_Registro!$N:$N,Detalhe_Registro!$D:$D,A2,Detalhe_Registro!$E:$E,B2,Detalhe_Registro!$M:$M,"SIM"),0) | G2: =IFERROR(AVERAGEIFS(Detalhe_Registro!$N:$N,Detalhe_Registro!$D:$D,A2,Detalhe_Registro!$E:$E,B2,Detalhe_Registro!$M:$M,"SIM"),0) | H2: =SUMIFS(Detalhe_Registro!$F:$F,Detalhe_Registro!$D:$D,A2,Detalhe_Registro!$E:$E,B2,Detalhe_Registro!$M:$M,"SIM") | I2: =SUMIFS(Detalhe_Registro!$G:$G,Detalhe_Registro!$D:$D,A2,Detalhe_Registro!$E:$E,B2,Detalhe_Registro!$M:$M,"SIM") | J2: =IF(F2<Premissas!$B$8,"< 1,00",IF(F2<Premissas!$B$9,"1,00 – 1,19",IF(F2<Premissas!$B$10,"1,20 – 1,39",IF(F2<Premissas!$B$11,"1,40 – 1,59",IF(F2<Premissas!$B$12,"1,60 – 1,99","≥ 2,00"))))) | K2: =IF(F2<Premissas!$B$8,Premissas!$B$13,IF(F2<Premissas!$B$9,Premissas!$B$14,IF(F2<Premissas!$B$10,Premissas!$B$15,IF(F2<Premissas!$B$11,Premissas!$B$16,IF(F2<Premissas!$B$12,Premissas!$B$17,Premissas!$B$18))))) | L2: =K2/Premissas!$B$4 | M2: =IF(K2=Premissas!$B$18,"SIM","NÃO")
A3: 5800609 | B3: Adriano Brito De Sa Fernandes | C3: 409 | D3: =IFERROR(TEXTJOIN(" | ",TRUE,UNIQUE(FILTER(Detalhe_Registro!$C:$C,(Detalhe_Registro!$D:$D=A3)*(Detalhe_Registro!$E:$E=B3)*(Detalhe_Registro!$M:$M="SIM")))),"") | E3: =COUNTIFS(Detalhe_Registro!$D:$D,A3,Detalhe_Registro!$E:$E,B3,Detalhe_Registro!$M:$M,"SIM") | F3: =IFERROR(MAXIFS(Detalhe_Registro!$N:$N,Detalhe_Registro!$D:$D,A3,Detalhe_Registro!$E:$E,B3,Detalhe_Registro!$M:$M,"SIM"),0) | G3: =IFERROR(AVERAGEIFS(Detalhe_Registro!$N:$N,Detalhe_Registro!$D:$D,A3,Detalhe_Registro!$E:$E,B3,Detalhe_Registro!$M:$M,"SIM"),0) | H3: =SUMIFS(Detalhe_Registro!$F:$F,Detalhe_Registro!$D:$D,A3,Detalhe_Registro!$E:$E,B3,Detalhe_Registro!$M:$M,"SIM") | I3: =SUMIFS(Detalhe_Registro!$G:$G,Detalhe_Registro!$D:$D,A3,Detalhe_Registro!$E:$E,B3,Detalhe_Registro!$M:$M,"SIM") | J3: =IF(F3<Premissas!$B$8,"< 1,00",IF(F3<Premissas!$B$9,"1,00 – 1,19",IF(F3<Premissas!$B$10,"1,20 – 1,39",IF(F3<Premissas!$B$11,"1,40 – 1,59",IF(F3<Premissas!$B$12,"1,60 – 1,99","≥ 2,00"))))) | K3: =IF(F3<Premissas!$B$8,Premissas!$B$13,IF(F3<Premissas!$B$9,Premissas!$B$14,IF(F3<Premissas!$B$10,Premissas!$B$15,IF(F3<Premissas!$B$11,Premissas!$B$16,IF(F3<Premissas!$B$12,Premissas!$B$17,Premissas!$B$18))))) | L3: =K3/Premissas!$B$4 | M3: =IF(K3=Premissas!$B$18,"SIM","NÃO")
A4: 5800609 | B4: Adriano Brito De Sa Fernandes | C4: 409 | D4: =IFERROR(TEXTJOIN(" | ",TRUE,UNIQUE(FILTER(Detalhe_Registro!$C:$C,(Detalhe_Registro!$D:$D=A4)*(Detalhe_Registro!$E:$E=B4)*(Detalhe_Registro!$M:$M="SIM")))),"") | E4: =COUNTIFS(Detalhe_Registro!$D:$D,A4,Detalhe_Registro!$E:$E,B4,Detalhe_Registro!$M:$M,"SIM") | F4: =IFERROR(MAXIFS(Detalhe_Registro!$N:$N,Detalhe_Registro!$D:$D,A4,Detalhe_Registro!$E:$E,B4,Detalhe_Registro!$M:$M,"SIM"),0) | G4: =IFERROR(AVERAGEIFS(Detalhe_Registro!$N:$N,Detalhe_Registro!$D:$D,A4,Detalhe_Registro!$E:$E,B4,Detalhe_Registro!$M:$M,"SIM"),0) | H4: =SUMIFS(Detalhe_Registro!$F:$F,Detalhe_Registro!$D:$D,A4,Detalhe_Registro!$E:$E,B4,Detalhe_Registro!$M:$M,"SIM") | I4: =SUMIFS(Detalhe_Registro!$G:$G,Detalhe_Registro!$D:$D,A4,Detalhe_Registro!$E:$E,B4,Detalhe_Registro!$M:$M,"SIM") | J4: =IF(F4<Premissas!$B$8,"< 1,00",IF(F4<Premissas!$B$9,"1,00 – 1,19",IF(F4<Premissas!$B$10,"1,20 – 1,39",IF(F4<Premissas!$B$11,"1,40 – 1,59",IF(F4<Premissas!$B$12,"1,60 – 1,99","≥ 2,00"))))) | K4: =IF(F4<Premissas!$B$8,Premissas!$B$13,IF(F4<Premissas!$B$9,Premissas!$B$14,IF(F4<Premissas!$B$10,Premissas!$B$15,IF(F4<Premissas!$B$11,Premissas!$B$16,IF(F4<Premissas!$B$12,Premissas!$B$17,Premissas!$B$18))))) | L4: =K4/Premissas!$B$4 | M4: =IF(K4=Premissas!$B$18,"SIM","NÃO")
A5: 5802040 | B5: Adriano Da Luz Maria | C5: 409 | D5: =IFERROR(TEXTJOIN(" | ",TRUE,UNIQUE(FILTER(Detalhe_Registro!$C:$C,(Detalhe_Registro!$D:$D=A5)*(Detalhe_Registro!$E:$E=B5)*(Detalhe_Registro!$M:$M="SIM")))),"") | E5: =COUNTIFS(Detalhe_Registro!$D:$D,A5,Detalhe_Registro!$E:$E,B5,Detalhe_Registro!$M:$M,"SIM") | F5: =IFERROR(MAXIFS(Detalhe_Registro!$N:$N,Detalhe_Registro!$D:$D,A5,Detalhe_Registro!$E:$E,B5,Detalhe_Registro!$M:$M,"SIM"),0) | G5: =IFERROR(AVERAGEIFS(Detalhe_Registro!$N:$N,Detalhe_Registro!$D:$D,A5,Detalhe_Registro!$E:$E,B5,Detalhe_Registro!$M:$M,"SIM"),0) | H5: =SUMIFS(Detalhe_Registro!$F:$F,Detalhe_Registro!$D:$D,A5,Detalhe_Registro!$E:$E,B5,Detalhe_Registro!$M:$M,"SIM") | I5: =SUMIFS(Detalhe_Registro!$G:$G,Detalhe_Registro!$D:$D,A5,Detalhe_Registro!$E:$E,B5,Detalhe_Registro!$M:$M,"SIM") | J5: =IF(F5<Premissas!$B$8,"< 1,00",IF(F5<Premissas!$B$9,"1,00 – 1,19",IF(F5<Premissas!$B$10,"1,20 – 1,39",IF(F5<Premissas!$B$11,"1,40 – 1,59",IF(F5<Premissas!$B$12,"1,60 – 1,99","≥ 2,00"))))) | K5: =IF(F5<Premissas!$B$8,Premissas!$B$13,IF(F5<Premissas!$B$9,Premissas!$B$14,IF(F5<Premissas!$B$10,Premissas!$B$15,IF(F5<Premissas!$B$11,Premissas!$B$16,IF(F5<Premissas!$B$12,Premissas!$B$17,Premissas!$B$18))))) | L5: =K5/Premissas!$B$4 | M5: =IF(K5=Premissas!$B$18,"SIM","NÃO")
A6: 5802040 | B6: Adriano Da Luz Maria | C6: 409 | D6: =IFERROR(TEXTJOIN(" | ",TRUE,UNIQUE(FILTER(Detalhe_Registro!$C:$C,(Detalhe_Registro!$D:$D=A6)*(Detalhe_Registro!$E:$E=B6)*(Detalhe_Registro!$M:$M="SIM")))),"") | E6: =COUNTIFS(Detalhe_Registro!$D:$D,A6,Detalhe_Registro!$E:$E,B6,Detalhe_Registro!$M:$M,"SIM") | F6: =IFERROR(MAXIFS(Detalhe_Registro!$N:$N,Detalhe_Registro!$D:$D,A6,Detalhe_Registro!$E:$E,B6,Detalhe_Registro!$M:$M,"SIM"),0) | G6: =IFERROR(AVERAGEIFS(Detalhe_Registro!$N:$N,Detalhe_Registro!$D:$D,A6,Detalhe_Registro!$E:$E,B6,Detalhe_Registro!$M:$M,"SIM"),0) | H6: =SUMIFS(Detalhe_Registro!$F:$F,Detalhe_Registro!$D:$D,A6,Detalhe_Registro!$E:$E,B6,Detalhe_Registro!$M:$M,"SIM") | I6: =SUMIFS(Detalhe_Registro!$G:$G,Detalhe_Registro!$D:$D,A6,Detalhe_Registro!$E:$E,B6,Detalhe_Registro!$M:$M,"SIM") | J6: =IF(F6<Premissas!$B$8,"< 1,00",IF(F6<Premissas!$B$9,"1,00 – 1,19",IF(F6<Premissas!$B$10,"1,20 – 1,39",IF(F6<Premissas!$B$11,"1,40 – 1,59",IF(F6<Premissas!$B$12,"1,60 – 1,99","≥ 2,00"))))) | K6: =IF(F6<Premissas!$B$8,Premissas!$B$13,IF(F6<Premissas!$B$9,Premissas!$B$14,IF(F6<Premissas!$B$10,Premissas!$B$15,IF(F6<Premissas!$B$11,Premissas!$B$16,IF(F6<Premissas!$B$12,Premissas!$B$17,Premissas!$B$18))))) | L6: =K6/Premissas!$B$4 | M6: =IF(K6=Premissas!$B$18,"SIM","NÃO")
A7: 5464285 | B7: Adriano Monteiro Da Silva | C7: 409 | D7: =IFERROR(TEXTJOIN(" | ",TRUE,UNIQUE(FILTER(Detalhe_Registro!$C:$C,(Detalhe_Registro!$D:$D=A7)*(Detalhe_Registro!$E:$E=B7)*(Detalhe_Registro!$M:$M="SIM")))),"") | E7: =COUNTIFS(Detalhe_Registro!$D:$D,A7,Detalhe_Registro!$E:$E,B7,Detalhe_Registro!$M:$M,"SIM") | F7: =IFERROR(MAXIFS(Detalhe_Registro!$N:$N,Detalhe_Registro!$D:$D,A7,Detalhe_Registro!$E:$E,B7,Detalhe_Registro!$M:$M,"SIM"),0) | G7: =IFERROR(AVERAGEIFS(Detalhe_Registro!$N:$N,Detalhe_Registro!$D:$D,A7,Detalhe_Registro!$E:$E,B7,Detalhe_Registro!$M:$M,"SIM"),0) | H7: =SUMIFS(Detalhe_Registro!$F:$F,Detalhe_Registro!$D:$D,A7,Detalhe_Registro!$E:$E,B7,Detalhe_Registro!$M:$M,"SIM") | I7: =SUMIFS(Detalhe_Registro!$G:$G,Detalhe_Registro!$D:$D,A7,Detalhe_Registro!$E:$E,B7,Detalhe_Registro!$M:$M,"SIM") | J7: =IF(F7<Premissas!$B$8,"< 1,00",IF(F7<Premissas!$B$9,"1,00 – 1,19",IF(F7<Premissas!$B$10,"1,20 – 1,39",IF(F7<Premissas!$B$11,"1,40 – 1,59",IF(F7<Premissas!$B$12,"1,60 – 1,99","≥ 2,00"))))) | K7: =IF(F7<Premissas!$B$8,Premissas!$B$13,IF(F7<Premissas!$B$9,Premissas!$B$14,IF(F7<Premissas!$B$10,Premissas!$B$15,IF(F7<Premissas!$B$11,Premissas!$B$16,IF(F7<Premissas!$B$12,Premissas!$B$17,Premissas!$B$18))))) | L7: =K7/Premissas!$B$4 | M7: =IF(K7=Premissas!$B$18,"SIM","NÃO")
A8: 5464285 | B8: Adriano Monteiro Da Silva | C8: 409 | D8: =IFERROR(TEXTJOIN(" | ",TRUE,UNIQUE(FILTER(Detalhe_Registro!$C:$C,(Detalhe_Registro!$D:$D=A8)*(Detalhe_Registro!$E:$E=B8)*(Detalhe_Registro!$M:$M="SIM")))),"") | E8: =COUNTIFS(Detalhe_Registro!$D:$D,A8,Detalhe_Registro!$E:$E,B8,Detalhe_Registro!$M:$M,"SIM") | F8: =IFERROR(MAXIFS(Detalhe_Registro!$N:$N,Detalhe_Registro!$D:$D,A8,Detalhe_Registro!$E:$E,B8,Detalhe_Registro!$M:$M,"SIM"),0) | G8: =IFERROR(AVERAGEIFS(Detalhe_Registro!$N:$N,Detalhe_Registro!$D:$D,A8,Detalhe_Registro!$E:$E,B8,Detalhe_Registro!$M:$M,"SIM"),0) | H8: =SUMIFS(Detalhe_Registro!$F:$F,Detalhe_Registro!$D:$D,A8,Detalhe_Registro!$E:$E,B8,Detalhe_Registro!$M:$M,"SIM") | I8: =SUMIFS(Detalhe_Registro!$G:$G,Detalhe_Registro!$D:$D,A8,Detalhe_Registro!$E:$E,B8,Detalhe_Registro!$M:$M,"SIM") | J8: =IF(F8<Premissas!$B$8,"< 1,00",IF(F8<Premissas!$B$9,"1,00 – 1,19",IF(F8<Premissas!$B$10,"1,20 – 1,39",IF(F8<Premissas!$B$11,"1,40 – 1,59",IF(F8<Premissas!$B$12,"1,60 – 1,99","≥ 2,00"))))) | K8: =IF(F8<Premissas!$B$8,Premissas!$B$13,IF(F8<Premissas!$B$9,Premissas!$B$14,IF(F8<Premissas!$B$10,Premissas!$B$15,IF(F8<Premissas!$B$11,Premissas!$B$16,IF(F8<Premissas!$B$12,Premissas!$B$17,Premissas!$B$18))))) | L8: =K8/Premissas!$B$4 | M8: =IF(K8=Premissas!$B$18,"SIM","NÃO")
A9: 5446082 | B9: Aleandro Oliveira Da Silva | C9: 409 | D9: =IFERROR(TEXTJOIN(" | ",TRUE,UNIQUE(FILTER(Detalhe_Registro!$C:$C,(Detalhe_Registro!$D:$D=A9)*(Detalhe_Registro!$E:$E=B9)*(Detalhe_Registro!$M:$M="SIM")))),"") | E9: =COUNTIFS(Detalhe_Registro!$D:$D,A9,Detalhe_Registro!$E:$E,B9,Detalhe_Registro!$M:$M,"SIM") | F9: =IFERROR(MAXIFS(Detalhe_Registro!$N:$N,Detalhe_Registro!$D:$D,A9,Detalhe_Registro!$E:$E,B9,Detalhe_Registro!$M:$M,"SIM"),0) | G9: =IFERROR(AVERAGEIFS(Detalhe_Registro!$N:$N,Detalhe_Registro!$D:$D,A9,Detalhe_Registro!$E:$E,B9,Detalhe_Registro!$M:$M,"SIM"),0) | H9: =SUMIFS(Detalhe_Registro!$F:$F,Detalhe_Registro!$D:$D,A9,Detalhe_Registro!$E:$E,B9,Detalhe_Registro!$M:$M,"SIM") | I9: =SUMIFS(Detalhe_Registro!$G:$G,Detalhe_Registro!$D:$D,A9,Detalhe_Registro!$E:$E,B9,Detalhe_Registro!$M:$M,"SIM") | J9: =IF(F9<Premissas!$B$8,"< 1,00",IF(F9<Premissas!$B$9,"1,00 – 1,19",IF(F9<Premissas!$B$10,"1,20 – 1,39",IF(F9<Premissas!$B$11,"1,40 – 1,59",IF(F9<Premissas!$B$12,"1,60 – 1,99","≥ 2,00"))))) | K9: =IF(F9<Premissas!$B$8,Premissas!$B$13,IF(F9<Premissas!$B$9,Premissas!$B$14,IF(F9<Premissas!$B$10,Premissas!$B$15,IF(F9<Premissas!$B$11,Premissas!$B$16,IF(F9<Premissas!$B$12,Premissas!$B$17,Premissas!$B$18))))) | L9: =K9/Premissas!$B$4 | M9: =IF(K9=Premissas!$B$18,"SIM","NÃO")
